<robot name="Artus3D_LeftHand">
<link name= "base_link"/>


<joint name="virtual" type="fixed">
<origin xyz="0 0 0" rpy="0 3.14 0"/>
<parent link="base_link"/>
<child link="left_-_forearm_and_palm_subassembly_copy_1"/>
</joint>

<link name="left_-_forearm_and_palm_subassembly_copy_1">
<visual>
<origin xyz="0.054879955648381877065 0.0076883312241074327695 0.008260321555686685191" rpy="1.570796326794896336 -8.0686821653843871675e-17 -3.141592653589793116" />
<geometry>
<mesh filename="meshes/7138k48_nano_m8_connector_6.stl"/>
</geometry>
<material name="7138k48_nano_m8_connector_6_material">
<color rgba="0.76862745098039220171 0.88627450980392152857 0.95294117647058818044 1.0"/>
</material>
</visual>
<collision>
<origin xyz="0.054879955648381877065 0.0076883312241074327695 0.008260321555686685191" rpy="1.570796326794896336 -8.0686821653843871675e-17 -3.141592653589793116" />
<geometry>
<mesh filename="meshes/7138k48_nano_m8_connector_6.stl"/>
</geometry>
</collision>
<visual>
<origin xyz="0.054879955648381974209 0.0076883312241073096041 0.0082603215556865429436" rpy="1.5707963267948779063 -2.2864627182922414808e-17 3.141592653589793116" />
<geometry>
<mesh filename="meshes/7138k48_nano_m8_connector_9.stl"/>
</geometry>
<material name="7138k48_nano_m8_connector_9_material">
<color rgba="0.98039215686274505668 0.71372549019607844922 0.0039215686274509803377 1.0"/>
</material>
</visual>
<collision>
<origin xyz="0.054879955648381974209 0.0076883312241073096041 0.0082603215556865429436" rpy="1.5707963267948779063 -2.2864627182922414808e-17 3.141592653589793116" />
<geometry>
<mesh filename="meshes/7138k48_nano_m8_connector_9.stl"/>
</geometry>
</collision>
<visual>
<origin xyz="0.054879955648381974209 0.0076883312241073096041 0.0082603215556865429436" rpy="1.5707963267948779063 -2.2864627182922414808e-17 3.141592653589793116" />
<geometry>
<mesh filename="meshes/7138k48_nano_m8_connector_12.stl"/>
</geometry>
<material name="7138k48_nano_m8_connector_12_material">
<color rgba="0.2313725490196078538 0.38039215686274507888 0.7058823529411765163 1.0"/>
</material>
</visual>
<collision>
<origin xyz="0.054879955648381974209 0.0076883312241073096041 0.0082603215556865429436" rpy="1.5707963267948779063 -2.2864627182922414808e-17 3.141592653589793116" />
<geometry>
<mesh filename="meshes/7138k48_nano_m8_connector_12.stl"/>
</geometry>
</collision>
<visual>
<origin xyz="0.10782996888245702238 0.17284073122410725798 0.013563106819823936289" rpy="0 -0 3.141592653589793116" />
<geometry>
<mesh filename="meshes/l_forearm_back_cover.stl"/>
</geometry>
<material name="l_forearm_back_cover_material">
<color rgba="0.26274509803921569651 0.28235294117647058432 0.30196078431372547213 1.0"/>
</material>
</visual>
<collision>
<origin xyz="0.10782996888245702238 0.17284073122410725798 0.013563106819823936289" rpy="0 -0 3.141592653589793116" />
<geometry>
<mesh filename="meshes/l_forearm_back_cover.stl"/>
</geometry>
</collision>
<visual>
<origin xyz="0.0080299688824571058277 0.25059073122410657763 0.0049131068198240649553" rpy="-1.613736433077298981e-16 1.3010426069826057152e-15 -1.5707963267948970021" />
<geometry>
<mesh filename="meshes/d5-_lring.stl"/>
</geometry>
<material name="d5-_lring_material">
<color rgba="0.76862745098039220171 0.88627450980392152857 0.95294117647058818044 1.0"/>
</material>
</visual>
<collision>
<origin xyz="0.0080299688824571058277 0.25059073122410657763 0.0049131068198240649553" rpy="-1.613736433077298981e-16 1.3010426069826057152e-15 -1.5707963267948970021" />
<geometry>
<mesh filename="meshes/d5-_lring.stl"/>
</geometry>
</collision>
<visual>
<origin xyz="0.035076299430739449337 0.24734466793926807027 0.0019131068198240622907" rpy="-2.4771671902375037252e-16 1.3489052410272972017e-15 -1.6406094968746700591" />
<geometry>
<mesh filename="meshes/d5-_lring.stl"/>
</geometry>
<material name="d5-_lring_material">
<color rgba="0.76862745098039220171 0.88627450980392152857 0.95294117647058818044 1.0"/>
</material>
</visual>
<collision>
<origin xyz="0.035076299430739449337 0.24734466793926807027 0.0019131068198240622907" rpy="-2.4771671902375037252e-16 1.3489052410272972017e-15 -1.6406094968746700591" />
<geometry>
<mesh filename="meshes/d5-_lring.stl"/>
</geometry>
</collision>
<visual>
<origin xyz="0.054879955648381877065 0.0076883312241074327695 0.008260321555686685191" rpy="1.570796326794896336 -8.0686821653843871675e-17 -3.141592653589793116" />
<geometry>
<mesh filename="meshes/7138k48_nano_m8_connector_1.stl"/>
</geometry>
<material name="7138k48_nano_m8_connector_1_material">
<color rgba="0.98039215686274505668 0.71372549019607844922 0.0039215686274509803377 1.0"/>
</material>
</visual>
<collision>
<origin xyz="0.054879955648381877065 0.0076883312241074327695 0.008260321555686685191" rpy="1.570796326794896336 -8.0686821653843871675e-17 -3.141592653589793116" />
<geometry>
<mesh filename="meshes/7138k48_nano_m8_connector_1.stl"/>
</geometry>
</collision>
<visual>
<origin xyz="0.054879955648381877065 0.0076883312241074327695 0.008260321555686685191" rpy="1.570796326794896336 -8.0686821653843871675e-17 -3.141592653589793116" />
<geometry>
<mesh filename="meshes/7138k48_nano_m8_connector_9.stl"/>
</geometry>
<material name="7138k48_nano_m8_connector_9_material">
<color rgba="0.98039215686274505668 0.71372549019607844922 0.0039215686274509803377 1.0"/>
</material>
</visual>
<collision>
<origin xyz="0.054879955648381877065 0.0076883312241074327695 0.008260321555686685191" rpy="1.570796326794896336 -8.0686821653843871675e-17 -3.141592653589793116" />
<geometry>
<mesh filename="meshes/7138k48_nano_m8_connector_9.stl"/>
</geometry>
</collision>
<visual>
<origin xyz="0.054879955648381877065 0.0076883312241074327695 0.008260321555686685191" rpy="1.570796326794896336 -8.0686821653843871675e-17 -3.141592653589793116" />
<geometry>
<mesh filename="meshes/7138k48_nano_m8_connector_11.stl"/>
</geometry>
<material name="7138k48_nano_m8_connector_11_material">
<color rgba="0.64705882352941179736 0.64705882352941179736 0.64705882352941179736 1.0"/>
</material>
</visual>
<collision>
<origin xyz="0.054879955648381877065 0.0076883312241074327695 0.008260321555686685191" rpy="1.570796326794896336 -8.0686821653843871675e-17 -3.141592653589793116" />
<geometry>
<mesh filename="meshes/7138k48_nano_m8_connector_11.stl"/>
</geometry>
</collision>
<visual>
<origin xyz="0.054879955648381877065 0.0076883312241074327695 0.008260321555686685191" rpy="1.570796326794896336 -8.0686821653843871675e-17 -3.141592653589793116" />
<geometry>
<mesh filename="meshes/7138k48_nano_m8_connector_5.stl"/>
</geometry>
<material name="7138k48_nano_m8_connector_5_material">
<color rgba="0.91764705882352937127 0.91764705882352937127 0.91764705882352937127 1.0"/>
</material>
</visual>
<collision>
<origin xyz="0.054879955648381877065 0.0076883312241074327695 0.008260321555686685191" rpy="1.570796326794896336 -8.0686821653843871675e-17 -3.141592653589793116" />
<geometry>
<mesh filename="meshes/7138k48_nano_m8_connector_5.stl"/>
</geometry>
</collision>
<visual>
<origin xyz="0.054879955648381974209 0.0076883312241073096041 0.0082603215556865429436" rpy="1.5707963267948779063 -2.2864627182922414808e-17 3.141592653589793116" />
<geometry>
<mesh filename="meshes/7138k48_nano_m8_connector_2.stl"/>
</geometry>
<material name="7138k48_nano_m8_connector_2_material">
<color rgba="0.61568627450980395466 0.81176470588235294379 0.92941176470588238168 1.0"/>
</material>
</visual>
<collision>
<origin xyz="0.054879955648381974209 0.0076883312241073096041 0.0082603215556865429436" rpy="1.5707963267948779063 -2.2864627182922414808e-17 3.141592653589793116" />
<geometry>
<mesh filename="meshes/7138k48_nano_m8_connector_2.stl"/>
</geometry>
</collision>
<visual>
<origin xyz="0.054879955648381974209 0.0076883312241073096041 0.0082603215556865429436" rpy="1.5707963267948779063 -2.2864627182922414808e-17 3.141592653589793116" />
<geometry>
<mesh filename="meshes/7138k48_nano_m8_connector_8.stl"/>
</geometry>
<material name="7138k48_nano_m8_connector_8_material">
<color rgba="0.49803921568627451677 0.49803921568627451677 0.49803921568627451677 1.0"/>
</material>
</visual>
<collision>
<origin xyz="0.054879955648381974209 0.0076883312241073096041 0.0082603215556865429436" rpy="1.5707963267948779063 -2.2864627182922414808e-17 3.141592653589793116" />
<geometry>
<mesh filename="meshes/7138k48_nano_m8_connector_8.stl"/>
</geometry>
</collision>
<visual>
<origin xyz="0.054879955648381877065 0.0076883312241074327695 0.008260321555686685191" rpy="1.570796326794896336 -8.0686821653843871675e-17 -3.141592653589793116" />
<geometry>
<mesh filename="meshes/7138k48_nano_m8_connector_3.stl"/>
</geometry>
<material name="7138k48_nano_m8_connector_3_material">
<color rgba="0.64705882352941179736 0.64705882352941179736 0.64705882352941179736 1.0"/>
</material>
</visual>
<collision>
<origin xyz="0.054879955648381877065 0.0076883312241074327695 0.008260321555686685191" rpy="1.570796326794896336 -8.0686821653843871675e-17 -3.141592653589793116" />
<geometry>
<mesh filename="meshes/7138k48_nano_m8_connector_3.stl"/>
</geometry>
</collision>
<visual>
<origin xyz="0.054879955648381877065 0.0076883312241074327695 0.008260321555686685191" rpy="1.570796326794896336 -8.0686821653843871675e-17 -3.141592653589793116" />
<geometry>
<mesh filename="meshes/7138k48_nano_m8_connector_8.stl"/>
</geometry>
<material name="7138k48_nano_m8_connector_8_material">
<color rgba="0.49803921568627451677 0.49803921568627451677 0.49803921568627451677 1.0"/>
</material>
</visual>
<collision>
<origin xyz="0.054879955648381877065 0.0076883312241074327695 0.008260321555686685191" rpy="1.570796326794896336 -8.0686821653843871675e-17 -3.141592653589793116" />
<geometry>
<mesh filename="meshes/7138k48_nano_m8_connector_8.stl"/>
</geometry>
</collision>
<visual>
<origin xyz="0.054879955648381974209 0.0076883312241073096041 0.0082603215556865429436" rpy="1.5707963267948779063 -2.2864627182922414808e-17 3.141592653589793116" />
<geometry>
<mesh filename="meshes/7138k48_nano_m8_connector_11.stl"/>
</geometry>
<material name="7138k48_nano_m8_connector_11_material">
<color rgba="0.64705882352941179736 0.64705882352941179736 0.64705882352941179736 1.0"/>
</material>
</visual>
<collision>
<origin xyz="0.054879955648381974209 0.0076883312241073096041 0.0082603215556865429436" rpy="1.5707963267948779063 -2.2864627182922414808e-17 3.141592653589793116" />
<geometry>
<mesh filename="meshes/7138k48_nano_m8_connector_11.stl"/>
</geometry>
</collision>
<visual>
<origin xyz="0.054879955648381877065 0.0076883312241074327695 0.008260321555686685191" rpy="1.570796326794896336 -8.0686821653843871675e-17 -3.141592653589793116" />
<geometry>
<mesh filename="meshes/7138k48_nano_m8_connector_10.stl"/>
</geometry>
<material name="7138k48_nano_m8_connector_10_material">
<color rgba="0.61568627450980395466 0.81176470588235294379 0.92941176470588238168 1.0"/>
</material>
</visual>
<collision>
<origin xyz="0.054879955648381877065 0.0076883312241074327695 0.008260321555686685191" rpy="1.570796326794896336 -8.0686821653843871675e-17 -3.141592653589793116" />
<geometry>
<mesh filename="meshes/7138k48_nano_m8_connector_10.stl"/>
</geometry>
</collision>
<visual>
<origin xyz="0.10782996888245702238 0.17284073122410725798 0.013563106819823936289" rpy="0 -0 3.141592653589793116" />
<geometry>
<mesh filename="meshes/l_pinky_side_forearm_cover.stl"/>
</geometry>
<material name="l_pinky_side_forearm_cover_material">
<color rgba="0.91764705882352937127 0.91764705882352937127 0.91764705882352937127 1.0"/>
</material>
</visual>
<collision>
<origin xyz="0.10782996888245702238 0.17284073122410725798 0.013563106819823936289" rpy="0 -0 3.141592653589793116" />
<geometry>
<mesh filename="meshes/l_pinky_side_forearm_cover.stl"/>
</geometry>
</collision>
<visual>
<origin xyz="0.022279968648382122987 0.015063331224107301409 0.0082603215556866903951" rpy="-1.570796326794896558 -1.5707963267948787944 0" />
<geometry>
<mesh filename="meshes/connector_2.stl"/>
</geometry>
<material name="connector_2_material">
<color rgba="0.79215686274509800047 0.81960784313725487671 0.93333333333333334814 1.0"/>
</material>
</visual>
<collision>
<origin xyz="0.022279968648382122987 0.015063331224107301409 0.0082603215556866903951" rpy="-1.570796326794896558 -1.5707963267948787944 0" />
<geometry>
<mesh filename="meshes/connector_2.stl"/>
</geometry>
</collision>
<visual>
<origin xyz="0.063795199711502548201 0.12025621774223599347 -0.083642017233696949741" rpy="-1.066316662172226204 -1.0057357117289822401 -3.1415926535897922278" />
<geometry>
<mesh filename="meshes/t5.stl"/>
</geometry>
<material name="t5_material">
<color rgba="0.76862745098039220171 0.88627450980392152857 0.95294117647058818044 1.0"/>
</material>
</visual>
<collision>
<origin xyz="0.063795199711502548201 0.12025621774223599347 -0.083642017233696949741" rpy="-1.066316662172226204 -1.0057357117289822401 -3.1415926535897922278" />
<geometry>
<mesh filename="meshes/t5.stl"/>
</geometry>
</collision>
<visual>
<origin xyz="0.017979967560434094442 0.01509220840014055369 -0.019726257885878662607" rpy="1.1839785150533513619e-17 -1.570796326794896558 0" />
<geometry>
<mesh filename="meshes/c-t4140l12041-000.stl"/>
</geometry>
<material name="c-t4140l12041-000_material">
<color rgba="0.6941176470588235059 0.74117647058823532547 0.78823529411764703401 1.0"/>
</material>
</visual>
<collision>
<origin xyz="0.017979967560434094442 0.01509220840014055369 -0.019726257885878662607" rpy="1.1839785150533513619e-17 -1.570796326794896558 0" />
<geometry>
<mesh filename="meshes/c-t4140l12041-000.stl"/>
</geometry>
</collision>
<visual>
<origin xyz="0.054879955648381974209 0.0076883312241073096041 0.0082603215556865429436" rpy="1.5707963267948779063 -2.2864627182922414808e-17 3.141592653589793116" />
<geometry>
<mesh filename="meshes/7138k48_nano_m8_connector_6.stl"/>
</geometry>
<material name="7138k48_nano_m8_connector_6_material">
<color rgba="0.76862745098039220171 0.88627450980392152857 0.95294117647058818044 1.0"/>
</material>
</visual>
<collision>
<origin xyz="0.054879955648381974209 0.0076883312241073096041 0.0082603215556865429436" rpy="1.5707963267948779063 -2.2864627182922414808e-17 3.141592653589793116" />
<geometry>
<mesh filename="meshes/7138k48_nano_m8_connector_6.stl"/>
</geometry>
</collision>
<visual>
<origin xyz="0.054879955648381877065 0.0076883312241074327695 0.008260321555686685191" rpy="1.570796326794896336 -8.0686821653843871675e-17 -3.141592653589793116" />
<geometry>
<mesh filename="meshes/7138k48_nano_m8_connector_7.stl"/>
</geometry>
<material name="7138k48_nano_m8_connector_7_material">
<color rgba="0.97254901960784312376 0.52941176470588235947 0.0039215686274509803377 1.0"/>
</material>
</visual>
<collision>
<origin xyz="0.054879955648381877065 0.0076883312241074327695 0.008260321555686685191" rpy="1.570796326794896336 -8.0686821653843871675e-17 -3.141592653589793116" />
<geometry>
<mesh filename="meshes/7138k48_nano_m8_connector_7.stl"/>
</geometry>
</collision>
<visual>
<origin xyz="-0.0079700311175427782789 0.172840731224104871 0.013563106819822480856" rpy="1.7374990335382516566e-14 5.133809799176772636e-30 3.141592653589793116" />
<geometry>
<mesh filename="meshes/forearm_front_heat_sink.stl"/>
</geometry>
<material name="forearm_front_heat_sink_material">
<color rgba="0.91764705882352937127 0.91764705882352937127 0.91764705882352937127 1.0"/>
</material>
</visual>
<collision>
<origin xyz="-0.0079700311175427782789 0.172840731224104871 0.013563106819822480856" rpy="1.7374990335382516566e-14 5.133809799176772636e-30 3.141592653589793116" />
<geometry>
<mesh filename="meshes/forearm_front_heat_sink.stl"/>
</geometry>
</collision>
<visual>
<origin xyz="0.054879955648381974209 0.0076883312241073096041 0.0082603215556865429436" rpy="1.5707963267948779063 -2.2864627182922414808e-17 3.141592653589793116" />
<geometry>
<mesh filename="meshes/7138k48_nano_m8_connector_10.stl"/>
</geometry>
<material name="7138k48_nano_m8_connector_10_material">
<color rgba="0.61568627450980395466 0.81176470588235294379 0.92941176470588238168 1.0"/>
</material>
</visual>
<collision>
<origin xyz="0.054879955648381974209 0.0076883312241073096041 0.0082603215556865429436" rpy="1.5707963267948779063 -2.2864627182922414808e-17 3.141592653589793116" />
<geometry>
<mesh filename="meshes/7138k48_nano_m8_connector_10.stl"/>
</geometry>
</collision>
<visual>
<origin xyz="0.10782996888245702238 0.17284073122410725798 0.013563106819823936289" rpy="0 -0 3.141592653589793116" />
<geometry>
<mesh filename="meshes/l_thumb_side_forearm_cover.stl"/>
</geometry>
<material name="l_thumb_side_forearm_cover_material">
<color rgba="0.91764705882352937127 0.91764705882352937127 0.91764705882352937127 1.0"/>
</material>
</visual>
<collision>
<origin xyz="0.10782996888245702238 0.17284073122410725798 0.013563106819823936289" rpy="0 -0 3.141592653589793116" />
<geometry>
<mesh filename="meshes/l_thumb_side_forearm_cover.stl"/>
</geometry>
</collision>
<visual>
<origin xyz="-0.03128830360089163154 -0.033881374576997511094 0.013563106819823943228" rpy="0 -1.4313686678903165613e-16 -3.05311331771919084e-16" />
<geometry>
<mesh filename="meshes/part_3.stl"/>
</geometry>
<material name="part_3_material">
<color rgba="0.2313725490196078538 0.38039215686274507888 0.7058823529411765163 1.0"/>
</material>
</visual>
<collision>
<origin xyz="-0.03128830360089163154 -0.033881374576997511094 0.013563106819823943228" rpy="0 -1.4313686678903165613e-16 -3.05311331771919084e-16" />
<geometry>
<mesh filename="meshes/part_3.stl"/>
</geometry>
</collision>
<visual>
<origin xyz="0.073436882148667934067 0.16826703430033540521 0.01356310681982392935" rpy="-1.9428902930940251783e-16 -5.5511151231257738274e-16 3.0019663134302465579" />
<geometry>
<mesh filename="meshes/left_palm_grip.stl"/>
</geometry>
<material name="left_palm_grip_material">
<color rgba="1 1 1 1.0"/>
</material>
</visual>
<collision>
<origin xyz="0.073436882148667934067 0.16826703430033540521 0.01356310681982392935" rpy="-1.9428902930940251783e-16 -5.5511151231257738274e-16 3.0019663134302465579" />
<geometry>
<mesh filename="meshes/left_palm_grip.stl"/>
</geometry>
</collision>
<visual>
<origin xyz="-0.031288303600891742562 -0.033881374576997844161 0.013563106819823950167" rpy="-9.5531463282139081189e-34 -1.4313686678903170543e-16 -3.0327332911414330937e-16" />
<geometry>
<mesh filename="meshes/part_4.stl"/>
</geometry>
<material name="part_4_material">
<color rgba="0.76862745098039220171 0.88627450980392152857 0.95294117647058818044 1.0"/>
</material>
</visual>
<collision>
<origin xyz="-0.031288303600891742562 -0.033881374576997844161 0.013563106819823950167" rpy="-9.5531463282139081189e-34 -1.4313686678903170543e-16 -3.0327332911414330937e-16" />
<geometry>
<mesh filename="meshes/part_4.stl"/>
</geometry>
</collision>
<visual>
<origin xyz="0.054879955648381974209 0.0076883312241073096041 0.0082603215556865429436" rpy="1.5707963267948779063 -2.2864627182922414808e-17 3.141592653589793116" />
<geometry>
<mesh filename="meshes/7138k48_nano_m8_connector_7.stl"/>
</geometry>
<material name="7138k48_nano_m8_connector_7_material">
<color rgba="0.97254901960784312376 0.52941176470588235947 0.0039215686274509803377 1.0"/>
</material>
</visual>
<collision>
<origin xyz="0.054879955648381974209 0.0076883312241073096041 0.0082603215556865429436" rpy="1.5707963267948779063 -2.2864627182922414808e-17 3.141592653589793116" />
<geometry>
<mesh filename="meshes/7138k48_nano_m8_connector_7.stl"/>
</geometry>
</collision>
<visual>
<origin xyz="0.054879955648381974209 0.0076883312241073096041 0.0082603215556865429436" rpy="1.5707963267948779063 -2.2864627182922414808e-17 3.141592653589793116" />
<geometry>
<mesh filename="meshes/7138k48_nano_m8_connector_3.stl"/>
</geometry>
<material name="7138k48_nano_m8_connector_3_material">
<color rgba="0.64705882352941179736 0.64705882352941179736 0.64705882352941179736 1.0"/>
</material>
</visual>
<collision>
<origin xyz="0.054879955648381974209 0.0076883312241073096041 0.0082603215556865429436" rpy="1.5707963267948779063 -2.2864627182922414808e-17 3.141592653589793116" />
<geometry>
<mesh filename="meshes/7138k48_nano_m8_connector_3.stl"/>
</geometry>
</collision>
<visual>
<origin xyz="0.054879955648381974209 0.0076883312241073096041 0.0082603215556865429436" rpy="1.5707963267948779063 -2.2864627182922414808e-17 3.141592653589793116" />
<geometry>
<mesh filename="meshes/7138k48_nano_m8_connector_4.stl"/>
</geometry>
<material name="7138k48_nano_m8_connector_4_material">
<color rgba="0.2313725490196078538 0.38039215686274507888 0.7058823529411765163 1.0"/>
</material>
</visual>
<collision>
<origin xyz="0.054879955648381974209 0.0076883312241073096041 0.0082603215556865429436" rpy="1.5707963267948779063 -2.2864627182922414808e-17 3.141592653589793116" />
<geometry>
<mesh filename="meshes/7138k48_nano_m8_connector_4.stl"/>
</geometry>
</collision>
<visual>
<origin xyz="0.054879955648381974209 0.0076883312241073096041 0.0082603215556865429436" rpy="1.5707963267948779063 -2.2864627182922414808e-17 3.141592653589793116" />
<geometry>
<mesh filename="meshes/7138k48_nano_m8_connector_1.stl"/>
</geometry>
<material name="7138k48_nano_m8_connector_1_material">
<color rgba="0.98039215686274505668 0.71372549019607844922 0.0039215686274509803377 1.0"/>
</material>
</visual>
<collision>
<origin xyz="0.054879955648381974209 0.0076883312241073096041 0.0082603215556865429436" rpy="1.5707963267948779063 -2.2864627182922414808e-17 3.141592653589793116" />
<geometry>
<mesh filename="meshes/7138k48_nano_m8_connector_1.stl"/>
</geometry>
</collision>
<visual>
<origin xyz="-0.018758373249789239701 0.24595684631360603678 0.0019131068198240935158" rpy="-7.4244371424405918453e-17 1.2489542737373337839e-15 -1.5009831567151239451" />
<geometry>
<mesh filename="meshes/d5_-_lmiddle.stl"/>
</geometry>
<material name="d5_-_lmiddle_material">
<color rgba="0.76862745098039220171 0.88627450980392152857 0.95294117647058818044 1.0"/>
</material>
</visual>
<collision>
<origin xyz="-0.018758373249789239701 0.24595684631360603678 0.0019131068198240935158" rpy="-7.4244371424405918453e-17 1.2489542737373337839e-15 -1.5009831567151239451" />
<geometry>
<mesh filename="meshes/d5_-_lmiddle.stl"/>
</geometry>
</collision>
<visual>
<origin xyz="0.054879955648381877065 0.0076883312241074327695 0.008260321555686685191" rpy="1.570796326794896336 -8.0686821653843871675e-17 -3.141592653589793116" />
<geometry>
<mesh filename="meshes/7138k48_nano_m8_connector_2.stl"/>
</geometry>
<material name="7138k48_nano_m8_connector_2_material">
<color rgba="0.61568627450980395466 0.81176470588235294379 0.92941176470588238168 1.0"/>
</material>
</visual>
<collision>
<origin xyz="0.054879955648381877065 0.0076883312241074327695 0.008260321555686685191" rpy="1.570796326794896336 -8.0686821653843871675e-17 -3.141592653589793116" />
<geometry>
<mesh filename="meshes/7138k48_nano_m8_connector_2.stl"/>
</geometry>
</collision>
<visual>
<origin xyz="0.10782996888245702238 0.17284073122410725798 0.013563106819823936289" rpy="0 -0 3.141592653589793116" />
<geometry>
<mesh filename="meshes/dim_part.stl"/>
</geometry>
<material name="dim_part_material">
<color rgba="0.91764705882352937127 0.91764705882352937127 0.91764705882352937127 1.0"/>
</material>
</visual>
<collision>
<origin xyz="0.10782996888245702238 0.17284073122410725798 0.013563106819823936289" rpy="0 -0 3.141592653589793116" />
<geometry>
<mesh filename="meshes/dim_part.stl"/>
</geometry>
</collision>
<visual>
<origin xyz="0.039179967560434084128 0.011805188473216271169 -0.020794275402046678153" rpy="1.57079632679489678 -1.753580260035135097e-14 -1.57079632679489678" />
<geometry>
<mesh filename="meshes/c-t41514c9l14-002.stl"/>
</geometry>
<material name="c-t41514c9l14-002_material">
<color rgba="0.61568627450980395466 0.81176470588235294379 0.92941176470588238168 1.0"/>
</material>
</visual>
<collision>
<origin xyz="0.039179967560434084128 0.011805188473216271169 -0.020794275402046678153" rpy="1.57079632679489678 -1.753580260035135097e-14 -1.57079632679489678" />
<geometry>
<mesh filename="meshes/c-t41514c9l14-002.stl"/>
</geometry>
</collision>
<visual>
<origin xyz="0.054879955648381974209 0.0076883312241073096041 0.0082603215556865429436" rpy="1.5707963267948779063 -2.2864627182922414808e-17 3.141592653589793116" />
<geometry>
<mesh filename="meshes/7138k48_nano_m8_connector_5.stl"/>
</geometry>
<material name="7138k48_nano_m8_connector_5_material">
<color rgba="0.91764705882352937127 0.91764705882352937127 0.91764705882352937127 1.0"/>
</material>
</visual>
<collision>
<origin xyz="0.054879955648381974209 0.0076883312241073096041 0.0082603215556865429436" rpy="1.5707963267948779063 -2.2864627182922414808e-17 3.141592653589793116" />
<geometry>
<mesh filename="meshes/7138k48_nano_m8_connector_5.stl"/>
</geometry>
</collision>
<visual>
<origin xyz="0.054879955648381877065 0.0076883312241074327695 0.008260321555686685191" rpy="1.570796326794896336 -8.0686821653843871675e-17 -3.141592653589793116" />
<geometry>
<mesh filename="meshes/7138k48_nano_m8_connector_12.stl"/>
</geometry>
<material name="7138k48_nano_m8_connector_12_material">
<color rgba="0.2313725490196078538 0.38039215686274507888 0.7058823529411765163 1.0"/>
</material>
</visual>
<collision>
<origin xyz="0.054879955648381877065 0.0076883312241074327695 0.008260321555686685191" rpy="1.570796326794896336 -8.0686821653843871675e-17 -3.141592653589793116" />
<geometry>
<mesh filename="meshes/7138k48_nano_m8_connector_12.stl"/>
</geometry>
</collision>
<visual>
<origin xyz="0.054879955648381877065 0.0076883312241074327695 0.008260321555686685191" rpy="1.570796326794896336 -8.0686821653843871675e-17 -3.141592653589793116" />
<geometry>
<mesh filename="meshes/7138k48_nano_m8_connector_4.stl"/>
</geometry>
<material name="7138k48_nano_m8_connector_4_material">
<color rgba="0.2313725490196078538 0.38039215686274507888 0.7058823529411765163 1.0"/>
</material>
</visual>
<collision>
<origin xyz="0.054879955648381877065 0.0076883312241074327695 0.008260321555686685191" rpy="1.570796326794896336 -8.0686821653843871675e-17 -3.141592653589793116" />
<geometry>
<mesh filename="meshes/7138k48_nano_m8_connector_4.stl"/>
</geometry>
</collision>
<visual>
<origin xyz="0.10782996888245702238 0.17284073122410725798 0.013563106819823936289" rpy="0 -0 3.141592653589793116" />
<geometry>
<mesh filename="meshes/l_forearm_front_cover.stl"/>
</geometry>
<material name="l_forearm_front_cover_material">
<color rgba="0.26274509803921569651 0.28235294117647058432 0.30196078431372547213 1.0"/>
</material>
</visual>
<collision>
<origin xyz="0.10782996888245702238 0.17284073122410725798 0.013563106819823936289" rpy="0 -0 3.141592653589793116" />
<geometry>
<mesh filename="meshes/l_forearm_front_cover.stl"/>
</geometry>
</collision>
<visual>
<origin xyz="-0.043264041709898476418 0.23804985426509689406 -0.001086893180175957721" rpy="1.3301558956251336654e-17 1.1921244715021859299e-15 -1.4486232791552937638" />
<geometry>
<mesh filename="meshes/d5_-_lindex.stl"/>
</geometry>
<material name="d5_-_lindex_material">
<color rgba="0.76862745098039220171 0.88627450980392152857 0.95294117647058818044 1.0"/>
</material>
</visual>
<collision>
<origin xyz="-0.043264041709898476418 0.23804985426509689406 -0.001086893180175957721" rpy="1.3301558956251336654e-17 1.1921244715021859299e-15 -1.4486232791552937638" />
<geometry>
<mesh filename="meshes/d5_-_lindex.stl"/>
</geometry>
</collision>
<inertial>
<origin xyz="-5.2941402447999662631e-05 0.028035487763612951945 -0.0020648475625446665281" rpy="0 0 0"/>
<mass value="0.16046300126368473471" />
<inertia ixx="0.00021183840702976855985" ixy="-7.9560914918038741734e-07"  ixz="-6.8078112096625444763e-07" iyy="0.0001553362613630856928" iyz="7.3329266511495605341e-06" izz="0.00021983078196426174885" />
</inertial>
</link>

<link name="part_1_3">
<visual>
<origin xyz="-0.0050000000000000044409 2.0816681711721685133e-17 -0.018500000000000099698" rpy="-1.4485681946286607074e-16 8.5979375613828706871e-16 4.5873601011248153631e-18" />
<geometry>
<mesh filename="meshes/part_1_3.stl"/>
</geometry>
<material name="part_1_3_material">
<color rgba="0.64705882352941179736 0.64705882352941179736 0.64705882352941179736 1.0"/>
</material>
</visual>
<collision>
<origin xyz="-0.0050000000000000044409 2.0816681711721685133e-17 -0.018500000000000099698" rpy="-1.4485681946286607074e-16 8.5979375613828706871e-16 4.5873601011248153631e-18" />
<geometry>
<mesh filename="meshes/part_1_3.stl"/>
</geometry>
</collision>
<inertial>
<origin xyz="0 0 0" rpy="0 0 0"/>
<mass value="0" />
<inertia ixx="0" ixy="0"  ixz="0" iyy="0" iyz="0" izz="0" />
</inertial>
</link>

<link name="part_1_8">
<visual>
<origin xyz="-0.028552407289709619276 -0.0078589767938891923887 -0.0060000000000051158244" rpy="-1.570796326794896558 9.2407166978388321345e-16 -1.9721522630525295135e-31" />
<geometry>
<mesh filename="meshes/part_1_8.stl"/>
</geometry>
<material name="part_1_8_material">
<color rgba="0.61568627450980395466 0.81176470588235294379 0.92941176470588238168 1.0"/>
</material>
</visual>
<collision>
<origin xyz="-0.028552407289709619276 -0.0078589767938891923887 -0.0060000000000051158244" rpy="-1.570796326794896558 9.2407166978388321345e-16 -1.9721522630525295135e-31" />
<geometry>
<mesh filename="meshes/part_1_8.stl"/>
</geometry>
</collision>
<inertial>
<origin xyz="0 0 0" rpy="0 0 0"/>
<mass value="0" />
<inertia ixx="0" ixy="0"  ixz="0" iyy="0" iyz="0" izz="0" />
</inertial>
</link>

<link name="part_1_9">
<visual>
<origin xyz="-0.017524803018038798141 -0.0071295923980055943281 -0.0052500000000001937478" rpy="-1.5707963267948970021 5.0861698098317028433e-16 0" />
<geometry>
<mesh filename="meshes/part_1_9.stl"/>
</geometry>
<material name="part_1_9_material">
<color rgba="0.91764705882352937127 0.91764705882352937127 0.91764705882352937127 1.0"/>
</material>
</visual>
<collision>
<origin xyz="-0.017524803018038798141 -0.0071295923980055943281 -0.0052500000000001937478" rpy="-1.5707963267948970021 5.0861698098317028433e-16 0" />
<geometry>
<mesh filename="meshes/part_1_9.stl"/>
</geometry>
</collision>
<inertial>
<origin xyz="0 0 0" rpy="0 0 0"/>
<mass value="0" />
<inertia ixx="0" ixy="0"  ixz="0" iyy="0" iyz="0" izz="0" />
</inertial>
</link>

<link name="d1_urdf_mk_5_3">
<visual>
<origin xyz="-0.0090000000000002022826 -0.006000000000000002727 -0.0047499999999967186526" rpy="-1.5707963267948961139 7.9983014192980559009e-17 0" />
<geometry>
<mesh filename="meshes/d1_urdf_mk_5_3.stl"/>
</geometry>
<material name="d1_urdf_mk_5_3_material">
<color rgba="0.2313725490196078538 0.38039215686274507888 0.7058823529411765163 1.0"/>
</material>
</visual>
<collision>
<origin xyz="-0.0090000000000002022826 -0.006000000000000002727 -0.0047499999999967186526" rpy="-1.5707963267948961139 7.9983014192980559009e-17 0" />
<geometry>
<mesh filename="meshes/d1_urdf_mk_5_3.stl"/>
</geometry>
</collision>
<inertial>
<origin xyz="0 0 0" rpy="0 0 0"/>
<mass value="0" />
<inertia ixx="0" ixy="0"  ixz="0" iyy="0" iyz="0" izz="0" />
</inertial>
</link>

<joint name="Lindex_34" type="revolute">
<origin xyz="-0.024999999999999994449 -7.0928506124001700073e-16 -0.00050000000000002299549" rpy="2.0066649276559482195e-29 -4.4883270483744882001e-17 4.8495448730108675262e-16" />
<parent link="part_1_9" />
<child link="d1_urdf_mk_5_3" />
<axis xyz="0 0 1"/>
<limit effort="1" velocity="20" lower="0" upper="1.570796326794896558"/>
<joint_properties friction="0.0"/>
</joint>

<joint name="Lindex_23" type="revolute">
<origin xyz="-0.038000000000001005196 0.00074999999999993626452 -0.00074999999999993301192" rpy="-1.203012880462042723e-29 3.41204581855675586e-16 1.4584499174773930989e-15" />
<parent link="part_1_8" />
<child link="part_1_9" />
<axis xyz="0 0 1"/>
<limit effort="1" velocity="20" lower="0" upper="1.570796326794896558"/>
<joint_properties friction="0.0"/>
</joint>

<joint name="Lindex_12" type="revolute">
<origin xyz="-0.014749999999999957589 -0.0059999999999999810429 -0.0095000000000000466016" rpy="1.570796326794896558 -2.1139226626773704015e-15 -5.7890059765448730555e-17" />
<parent link="part_1_3" />
<child link="part_1_8" />
<axis xyz="0 0 1"/>
<limit effort="1" velocity="20" lower="0" upper="1.570796326794896558"/>
<joint_properties friction="0.0"/>
</joint>

<joint name="Lindex_01" type="revolute">
<origin xyz="0.029652733597133662524 0.16978406303156654 0.010663106819823960775" rpy="-2.4771671902211570481e-16 4.8154350303710264446e-16 -1.6406094968746700591" />
<parent link="left_-_forearm_and_palm_subassembly_copy_1" />
<child link="part_1_3" />
<axis xyz="0 0 1"/>
<limit effort="1" velocity="20" lower="-0.29670597283903604735" upper="0.29670597283903604735"/>
<joint_properties friction="0.0"/>
</joint>

<link name="part_1_2">
<visual>
<origin xyz="-0.0050000000000000044409 1.6696713456276768284e-17 -0.018500000000000099698" rpy="-1.4485681946286607074e-16 8.597937561382868715e-16 -1.4339799225139642273e-17" />
<geometry>
<mesh filename="meshes/part_1_2.stl"/>
</geometry>
<material name="part_1_2_material">
<color rgba="0.64705882352941179736 0.64705882352941179736 0.64705882352941179736 1.0"/>
</material>
</visual>
<collision>
<origin xyz="-0.0050000000000000044409 1.6696713456276768284e-17 -0.018500000000000099698" rpy="-1.4485681946286607074e-16 8.597937561382868715e-16 -1.4339799225139642273e-17" />
<geometry>
<mesh filename="meshes/part_1_2.stl"/>
</geometry>
</collision>
<inertial>
<origin xyz="0 0 0" rpy="0 0 0"/>
<mass value="0" />
<inertia ixx="0" ixy="0"  ixz="0" iyy="0" iyz="0" izz="0" />
</inertial>
</link>

<link name="part_1_7">
<visual>
<origin xyz="-0.028552407289709647031 -0.0078589767938891923887 -0.0060000000000051140897" rpy="-1.570796326794896558 9.1526915033679976139e-16 0" />
<geometry>
<mesh filename="meshes/part_1_7.stl"/>
</geometry>
<material name="part_1_7_material">
<color rgba="0.61568627450980395466 0.81176470588235294379 0.92941176470588238168 1.0"/>
</material>
</visual>
<collision>
<origin xyz="-0.028552407289709647031 -0.0078589767938891923887 -0.0060000000000051140897" rpy="-1.570796326794896558 9.1526915033679976139e-16 0" />
<geometry>
<mesh filename="meshes/part_1_7.stl"/>
</geometry>
</collision>
<inertial>
<origin xyz="0 0 0" rpy="0 0 0"/>
<mass value="0" />
<inertia ixx="0" ixy="0"  ixz="0" iyy="0" iyz="0" izz="0" />
</inertial>
</link>

<link name="part_1_11">
<visual>
<origin xyz="-0.017524803018038770386 -0.0071295923980049125818 -0.0052500000000001972172" rpy="-1.5707963267948970021 5.1823007402470732895e-16 0" />
<geometry>
<mesh filename="meshes/part_1_11.stl"/>
</geometry>
<material name="part_1_11_material">
<color rgba="0.91764705882352937127 0.91764705882352937127 0.91764705882352937127 1.0"/>
</material>
</visual>
<collision>
<origin xyz="-0.017524803018038770386 -0.0071295923980049125818 -0.0052500000000001972172" rpy="-1.5707963267948970021 5.1823007402470732895e-16 0" />
<geometry>
<mesh filename="meshes/part_1_11.stl"/>
</geometry>
</collision>
<inertial>
<origin xyz="0 0 0" rpy="0 0 0"/>
<mass value="0" />
<inertia ixx="0" ixy="0"  ixz="0" iyy="0" iyz="0" izz="0" />
</inertial>
</link>

<link name="d1_urdf_mk_5_4">
<visual>
<origin xyz="-0.0090000000000002300382 -0.0060000000000000035943 -0.0047499999999967203873" rpy="-1.5707963267948961139 8.8421966871375079061e-17 -2.3641221439399485555e-31" />
<geometry>
<mesh filename="meshes/d1_urdf_mk_5_4.stl"/>
</geometry>
<material name="d1_urdf_mk_5_4_material">
<color rgba="0.2313725490196078538 0.38039215686274507888 0.7058823529411765163 1.0"/>
</material>
</visual>
<collision>
<origin xyz="-0.0090000000000002300382 -0.0060000000000000035943 -0.0047499999999967203873" rpy="-1.5707963267948961139 8.8421966871375079061e-17 -2.3641221439399485555e-31" />
<geometry>
<mesh filename="meshes/d1_urdf_mk_5_4.stl"/>
</geometry>
</collision>
<inertial>
<origin xyz="0 0 0" rpy="0 0 0"/>
<mass value="0" />
<inertia ixx="0" ixy="0"  ixz="0" iyy="0" iyz="0" izz="0" />
</inertial>
</link>

<joint name="Lring_34" type="revolute">
<origin xyz="-0.024999999999999938938 -2.645453300864630819e-17 -0.00050000000000002212813" rpy="-4.6820137604398950592e-25 -4.0365766663570789377e-17 5.6101978012472483357e-17" />
<parent link="part_1_11" />
<child link="d1_urdf_mk_5_4" />
<axis xyz="0 0 1"/>
<limit effort="1" velocity="20" lower="0" upper="1.570796326794896558"/>
<joint_properties friction="0.0"/>
</joint>

<joint name="Lring_23" type="revolute">
<origin xyz="-0.038000000000001032952 0.00074999999999993973397 -0.00074999999999997377792" rpy="-7.6149513552962997927e-25 3.2096615247806722106e-16 -5.4165836784305664591e-17" />
<parent link="part_1_7" />
<child link="part_1_11" />
<axis xyz="0 0 1"/>
<limit effort="1" velocity="20" lower="0" upper="1.570796326794896558"/>
<joint_properties friction="0.0"/>
</joint>

<joint name="Lring_12" type="revolute">
<origin xyz="-0.014749999999999957589 -0.0060000000000000079312 -0.0095000000000000431322" rpy="1.570796326794896558 8.6342401206296741349e-16 -9.1473262590972008691e-17" />
<parent link="part_1_2" />
<child link="part_1_7" />
<axis xyz="0 0 1"/>
<limit effort="1" velocity="20" lower="0" upper="1.570796326794896558"/>
<joint_properties friction="0.0"/>
</joint>

<joint name="Lring_01" type="revolute">
<origin xyz="-0.01333480741618353789 0.16839624140590458978 0.010663106819823998939" rpy="-7.4244371424256663504e-17 3.8159253574891327622e-16 -1.5009831567149312104" />
<parent link="left_-_forearm_and_palm_subassembly_copy_1" />
<child link="part_1_2" />
<axis xyz="0 0 1"/>
<limit effort="1" velocity="20" lower="-0.29670597283903604735" upper="0.29670597283903604735"/>
<joint_properties friction="0.0"/>
</joint>

<link name="part_1_4">
<visual>
<origin xyz="-0.0050000000000000044409 1.2143064331837649661e-17 -0.018500000000000103167" rpy="-1.4485681946286604609e-16 8.5979375613828706871e-16 7.3147244699295210759e-32" />
<geometry>
<mesh filename="meshes/part_1_4.stl"/>
</geometry>
<material name="part_1_4_material">
<color rgba="0.64705882352941179736 0.64705882352941179736 0.64705882352941179736 1.0"/>
</material>
</visual>
<collision>
<origin xyz="-0.0050000000000000044409 1.2143064331837649661e-17 -0.018500000000000103167" rpy="-1.4485681946286604609e-16 8.5979375613828706871e-16 7.3147244699295210759e-32" />
<geometry>
<mesh filename="meshes/part_1_4.stl"/>
</geometry>
</collision>
<inertial>
<origin xyz="0 0 0" rpy="0 0 0"/>
<mass value="0" />
<inertia ixx="0" ixy="0"  ixz="0" iyy="0" iyz="0" izz="0" />
</inertial>
</link>

<link name="part_1_5">
<visual>
<origin xyz="-0.028552407289709619276 -0.0078589767938891941235 -0.0060000000000051158244" rpy="-1.570796326794896558 9.1312390131153511741e-16 1.7765682715981165162e-31" />
<geometry>
<mesh filename="meshes/part_1_5.stl"/>
</geometry>
<material name="part_1_5_material">
<color rgba="0.61568627450980395466 0.81176470588235294379 0.92941176470588238168 1.0"/>
</material>
</visual>
<collision>
<origin xyz="-0.028552407289709619276 -0.0078589767938891941235 -0.0060000000000051158244" rpy="-1.570796326794896558 9.1312390131153511741e-16 1.7765682715981165162e-31" />
<geometry>
<mesh filename="meshes/part_1_5.stl"/>
</geometry>
</collision>
<inertial>
<origin xyz="0 0 0" rpy="0 0 0"/>
<mass value="0" />
<inertia ixx="0" ixy="0"  ixz="0" iyy="0" iyz="0" izz="0" />
</inertial>
</link>

<link name="part_1_10">
<visual>
<origin xyz="-0.017524803018038770386 -0.0071295923980049125818 -0.0052500000000001972172" rpy="-1.5707963267948970021 5.1781495757909476566e-16 -3.9443045261050590271e-31" />
<geometry>
<mesh filename="meshes/part_1_10.stl"/>
</geometry>
<material name="part_1_10_material">
<color rgba="0.91764705882352937127 0.91764705882352937127 0.91764705882352937127 1.0"/>
</material>
</visual>
<collision>
<origin xyz="-0.017524803018038770386 -0.0071295923980049125818 -0.0052500000000001972172" rpy="-1.5707963267948970021 5.1781495757909476566e-16 -3.9443045261050590271e-31" />
<geometry>
<mesh filename="meshes/part_1_10.stl"/>
</geometry>
</collision>
<inertial>
<origin xyz="0 0 0" rpy="0 0 0"/>
<mass value="0" />
<inertia ixx="0" ixy="0"  ixz="0" iyy="0" iyz="0" izz="0" />
</inertial>
</link>

<link name="d1_urdf_mk_5_2">
<visual>
<origin xyz="-0.0090000000000002300382 -0.005999999999999961961 -0.0047499999999967203873" rpy="-1.5707963267948961139 8.3887279286789822708e-17 0" />
<geometry>
<mesh filename="meshes/d1_urdf_mk_5_2.stl"/>
</geometry>
<material name="d1_urdf_mk_5_2_material">
<color rgba="0.2313725490196078538 0.38039215686274507888 0.7058823529411765163 1.0"/>
</material>
</visual>
<collision>
<origin xyz="-0.0090000000000002300382 -0.005999999999999961961 -0.0047499999999967203873" rpy="-1.5707963267948961139 8.3887279286789822708e-17 0" />
<geometry>
<mesh filename="meshes/d1_urdf_mk_5_2.stl"/>
</geometry>
</collision>
<inertial>
<origin xyz="0 0 0" rpy="0 0 0"/>
<mass value="0" />
<inertia ixx="0" ixy="0"  ixz="0" iyy="0" iyz="0" izz="0" />
</inertial>
</link>

<joint name="Lmiddle_34" type="revolute">
<origin xyz="-0.025000000000000022204 -2.6888213877640509963e-17 -0.00049999999999999307151" rpy="-1.2709521987871855322e-17 -6.9135862519869839114e-16 2.4424906541751933221e-15" />
<parent link="part_1_10" />
<child link="d1_urdf_mk_5_2" />
<axis xyz="0 0 1"/>
<limit effort="1" velocity="20" lower="0" upper="1.570796326794896558"/>
<joint_properties friction="0.0"/>
</joint>

<joint name="Lmiddle_23" type="revolute">
<origin xyz="-0.038000000000001060707 0.00074999999999993734873 -0.00074999999999999893141" rpy="6.7528543949465342288e-15 -6.1407648507694162046e-15 -1.1160838221474575544e-15" />
<parent link="part_1_5" />
<child link="part_1_10" />
<axis xyz="0 0 1"/>
<limit effort="1" velocity="20" lower="0" upper="1.570796326794896558"/>
<joint_properties friction="0.0"/>
</joint>

<joint name="Lmiddle_12" type="revolute">
<origin xyz="-0.014749999999999985345 -0.0060000000000000226763 -0.0095000000000000431322" rpy="1.570796326794896336 1.0759775635408031871e-15 8.0772178685727677249e-16" />
<parent link="part_1_4" />
<child link="part_1_5" />
<axis xyz="0 0 1"/>
<limit effort="1" velocity="20" lower="0" upper="1.570796326794896558"/>
<joint_properties friction="0.0"/>
</joint>

<joint name="Lmiddle_01" type="revolute">
<origin xyz="0.008029968882457065929 0.17284073122410698042 0.013663106819823966909" rpy="-1.6137364330754959408e-16 4.3368086899388746184e-16 -1.5707963267948970021" />
<parent link="left_-_forearm_and_palm_subassembly_copy_1" />
<child link="part_1_4" />
<axis xyz="0 0 1"/>
<limit effort="1" velocity="20" lower="-0.29670597283903604735" upper="0.29670597283903604735"/>
<joint_properties friction="0.0"/>
</joint>

<link name="part_1_1">
<visual>
<origin xyz="-0.0050000000000000044409 1.3877787807814456755e-17 -0.018500000000000099698" rpy="-1.4485681946286607074e-16 8.5979375613828706871e-16 -1.2251454207773070243e-17" />
<geometry>
<mesh filename="meshes/part_1_1.stl"/>
</geometry>
<material name="part_1_1_material">
<color rgba="0.64705882352941179736 0.64705882352941179736 0.64705882352941179736 1.0"/>
</material>
</visual>
<collision>
<origin xyz="-0.0050000000000000044409 1.3877787807814456755e-17 -0.018500000000000099698" rpy="-1.4485681946286607074e-16 8.5979375613828706871e-16 -1.2251454207773070243e-17" />
<geometry>
<mesh filename="meshes/part_1_1.stl"/>
</geometry>
</collision>
<inertial>
<origin xyz="0 0 0" rpy="0 0 0"/>
<mass value="0" />
<inertia ixx="0" ixy="0"  ixz="0" iyy="0" iyz="0" izz="0" />
</inertial>
</link>

<link name="part_1_6">
<visual>
<origin xyz="-0.028552407289709647031 -0.0078589767938891073873 -0.0060000000000051314369" rpy="-1.570796326794896558 8.9966941061623328137e-16 1.2340869757317796685e-31" />
<geometry>
<mesh filename="meshes/part_1_6.stl"/>
</geometry>
<material name="part_1_6_material">
<color rgba="0.61568627450980395466 0.81176470588235294379 0.92941176470588238168 1.0"/>
</material>
</visual>
<collision>
<origin xyz="-0.028552407289709647031 -0.0078589767938891073873 -0.0060000000000051314369" rpy="-1.570796326794896558 8.9966941061623328137e-16 1.2340869757317796685e-31" />
<geometry>
<mesh filename="meshes/part_1_6.stl"/>
</geometry>
</collision>
<inertial>
<origin xyz="0 0 0" rpy="0 0 0"/>
<mass value="0" />
<inertia ixx="0" ixy="0"  ixz="0" iyy="0" iyz="0" izz="0" />
</inertial>
</link>

<link name="part_1_12">
<visual>
<origin xyz="-0.017524803018038770386 -0.0071295923980055925934 -0.005250000000000198952" rpy="-1.5707963267948970021 5.2907400671596298389e-16 7.5754338914812962462e-32" />
<geometry>
<mesh filename="meshes/part_1_12.stl"/>
</geometry>
<material name="part_1_12_material">
<color rgba="0.91764705882352937127 0.91764705882352937127 0.91764705882352937127 1.0"/>
</material>
</visual>
<collision>
<origin xyz="-0.017524803018038770386 -0.0071295923980055925934 -0.005250000000000198952" rpy="-1.5707963267948970021 5.2907400671596298389e-16 7.5754338914812962462e-32" />
<geometry>
<mesh filename="meshes/part_1_12.stl"/>
</geometry>
</collision>
<inertial>
<origin xyz="0 0 0" rpy="0 0 0"/>
<mass value="0" />
<inertia ixx="0" ixy="0"  ixz="0" iyy="0" iyz="0" izz="0" />
</inertial>
</link>

<link name="d1_urdf_mk_5_1">
<visual>
<origin xyz="-0.0090000000000002022826 -0.005999999999999961961 -0.0047499999999967203873" rpy="-1.5707963267948961139 7.2078656972232345122e-17 1.9721522630525295135e-31" />
<geometry>
<mesh filename="meshes/d1_urdf_mk_5_1.stl"/>
</geometry>
<material name="d1_urdf_mk_5_1_material">
<color rgba="0.2313725490196078538 0.38039215686274507888 0.7058823529411765163 1.0"/>
</material>
</visual>
<collision>
<origin xyz="-0.0090000000000002022826 -0.005999999999999961961 -0.0047499999999967203873" rpy="-1.5707963267948961139 7.2078656972232345122e-17 1.9721522630525295135e-31" />
<geometry>
<mesh filename="meshes/d1_urdf_mk_5_1.stl"/>
</geometry>
</collision>
<inertial>
<origin xyz="0 0 0" rpy="0 0 0"/>
<mass value="0" />
<inertia ixx="0" ixy="0"  ixz="0" iyy="0" iyz="0" izz="0" />
</inertial>
</link>

<joint name="Lpinky_34" type="revolute">
<origin xyz="-0.024999999999999938938 -7.097187421090112025e-16 -0.00049999999999996921907" rpy="2.4742140836575812771e-15 6.5241778583844836993e-15 -7.3963954661431224342e-16" />
<parent link="part_1_12" />
<child link="d1_urdf_mk_5_1" />
<axis xyz="0 0 1"/>
<limit effort="1" velocity="20" lower="0" upper="1.570796326794896558"/>
<joint_properties friction="0.0"/>
</joint>

<joint name="Lpinky_23" type="revolute">
<origin xyz="-0.038000000000001060707 0.00075000000000002473542 -0.00075000000000001801337" rpy="-2.1529034789365982452e-15 -4.7613750562082510911e-15 6.7302926209106530169e-16" />
<parent link="part_1_6" />
<child link="part_1_12" />
<axis xyz="0 0 1"/>
<limit effort="1" velocity="20" lower="0" upper="1.570796326794896558"/>
<joint_properties friction="0.0"/>
</joint>

<joint name="Lpinky_12" type="revolute">
<origin xyz="-0.014749999999999929834 -0.006000000000000024411 -0.0095000000000000431322" rpy="1.570796326794896558 8.0407598349801679937e-16 -1.5814339539472369399e-15" />
<parent link="part_1_1" />
<child link="part_1_6" />
<axis xyz="0 0 1"/>
<limit effort="1" velocity="20" lower="0" upper="1.570796326794896558"/>
<joint_properties friction="0.0"/>
</joint>

<joint name="Lpinky_01" type="revolute">
<origin xyz="-0.033788700260148282761 0.16087939097498410446 0.007663106819823952906" rpy="1.3301558927690134543e-17 3.2476273355292699202e-16 -1.4486232791551669763" />
<parent link="left_-_forearm_and_palm_subassembly_copy_1" />
<child link="part_1_1" />
<axis xyz="0 0 1"/>
<limit effort="1" velocity="20" lower="-0.29670597283903604735" upper="0.29670597283903604735"/>
<joint_properties friction="0.0"/>
</joint>

<link name="part_1_17">
<visual>
<origin xyz="-0.0049999999999999905631 1.3877787807814456755e-17 0.00062867965644036738482" rpy="-3.141592653589793116 -2.2603966484490559575e-17 1.641780634130188085e-17" />
<geometry>
<mesh filename="meshes/part_1_17.stl"/>
</geometry>
<material name="part_1_17_material">
<color rgba="0.2313725490196078538 0.38039215686274507888 0.7058823529411765163 1.0"/>
</material>
</visual>
<collision>
<origin xyz="-0.0049999999999999905631 1.3877787807814456755e-17 0.00062867965644036738482" rpy="-3.141592653589793116 -2.2603966484490559575e-17 1.641780634130188085e-17" />
<geometry>
<mesh filename="meshes/part_1_17.stl"/>
</geometry>
</collision>
<inertial>
<origin xyz="0 0 0" rpy="0 0 0"/>
<mass value="0" />
<inertia ixx="0" ixy="0"  ixz="0" iyy="0" iyz="0" izz="0" />
</inertial>
</link>

<link name="part_1_18">
<visual>
<origin xyz="-0.02927735623681019389 -0.0078134566939178223821 -0.0067500000000003251843" rpy="-1.5707963267948961139 4.3846207487402675317e-16 -1.0428547370441645257e-17" />
<geometry>
<mesh filename="meshes/part_1_18.stl"/>
</geometry>
<material name="part_1_18_material">
<color rgba="0.64705882352941179736 0.64705882352941179736 0.64705882352941179736 1.0"/>
</material>
</visual>
<collision>
<origin xyz="-0.02927735623681019389 -0.0078134566939178223821 -0.0067500000000003251843" rpy="-1.5707963267948961139 4.3846207487402675317e-16 -1.0428547370441645257e-17" />
<geometry>
<mesh filename="meshes/part_1_18.stl"/>
</geometry>
</collision>
<inertial>
<origin xyz="0 0 0" rpy="0 0 0"/>
<mass value="0" />
<inertia ixx="0" ixy="0"  ixz="0" iyy="0" iyz="0" izz="0" />
</inertial>
</link>

<link name="part_1_19">
<visual>
<origin xyz="-0.01752480301803861773 -0.0071295923980051884028 -0.0062499999999999361622" rpy="-1.57079632679489678 5.8655132357618849585e-16 1.0573383494856618304e-17" />
<geometry>
<mesh filename="meshes/part_1_19.stl"/>
</geometry>
<material name="part_1_19_material">
<color rgba="0.61568627450980395466 0.81176470588235294379 0.92941176470588238168 1.0"/>
</material>
</visual>
<collision>
<origin xyz="-0.01752480301803861773 -0.0071295923980051884028 -0.0062499999999999361622" rpy="-1.57079632679489678 5.8655132357618849585e-16 1.0573383494856618304e-17" />
<geometry>
<mesh filename="meshes/part_1_19.stl"/>
</geometry>
</collision>
<inertial>
<origin xyz="0 0 0" rpy="0 0 0"/>
<mass value="0" />
<inertia ixx="0" ixy="0"  ixz="0" iyy="0" iyz="0" izz="0" />
</inertial>
</link>

<link name="part_1_20">
<visual>
<origin xyz="-0.0089999999999997304378 -0.0060000000000001024736 -0.0057500000000045292659" rpy="-1.570796326794896558 2.7659581394880849102e-16 -3.2451090108264882345e-17" />
<geometry>
<mesh filename="meshes/part_1_20.stl"/>
</geometry>
<material name="part_1_20_material">
<color rgba="0.49803921568627451677 0.49803921568627451677 0.49803921568627451677 1.0"/>
</material>
</visual>
<collision>
<origin xyz="-0.0089999999999997304378 -0.0060000000000001024736 -0.0057500000000045292659" rpy="-1.570796326794896558 2.7659581394880849102e-16 -3.2451090108264882345e-17" />
<geometry>
<mesh filename="meshes/part_1_20.stl"/>
</geometry>
</collision>
<inertial>
<origin xyz="0 0 0" rpy="0 0 0"/>
<mass value="0" />
<inertia ixx="0" ixy="0"  ixz="0" iyy="0" iyz="0" izz="0" />
</inertial>
</link>

<joint name="Lthumb_34" type="revolute">
<origin xyz="-0.02499999999999967526 -4.1633363423443370266e-16 0.0010000000000001812994" rpy="-4.688261135798667998e-15 5.1314037363500808475e-15 -2.2740228943043686611e-14" />
<parent link="part_1_19" />
<child link="part_1_20" />
<axis xyz="0 0 1"/>
<limit effort="1" velocity="20" lower="0" upper="1.570796326794896558"/>
<joint_properties friction="0.0"/>
</joint>

<joint name="Lthumb_23" type="revolute">
<origin xyz="-0.038000000000000734579 0.00075000000000007005507 -0.00050000000000002819966" rpy="7.9795674991893524016e-15 -6.9940128816369752248e-16 2.9241053137382957057e-14" />
<parent link="part_1_18" />
<child link="part_1_19" />
<axis xyz="0 0 1"/>
<limit effort="1" velocity="20" lower="0" upper="1.570796326794896558"/>
<joint_properties friction="0.0"/>
</joint>

<joint name="Lthumb_12" type="revolute">
<origin xyz="-0.014750000000000006162 0.0067499999999999782396 -0.0077500000000000485167" rpy="-1.570796326794896558 -2.6958623546826084004e-14 1.0018716920633894887e-15" />
<parent link="part_1_17" />
<child link="part_1_18" />
<axis xyz="0 0 1"/>
<limit effort="1" velocity="20" lower="0" upper="1.570796326794896558"/>
<joint_properties friction="0.0"/>
</joint>

<joint name="Lthumb_01" type="revolute">
<origin xyz="0.018692787601649763635 0.12769733957579351702 -0.020177738873889142224" rpy="2.0752759914176541756 -1.0057357117290488535 3.1415926535897256144" />
<parent link="left_-_forearm_and_palm_subassembly_copy_1" />
<child link="part_1_17" />
<axis xyz="0 0 1"/>
<limit effort="1" velocity="20" lower="-0.64577182323790194296" upper="0.64577182323790194296"/>
<joint_properties friction="0.0"/>
</joint>


</robot>
