<robot name="ArtusLite_LeftHand">

    <link name="base_link"/>
    
    <joint name="virtual" type="fixed">
    <origin xyz="0 0 0" rpy="1.67 0 0"/>
    <parent link="base_link"/>
    <child link="left_forearm_and_palm_assembly"/>
    </joint>

    
<link name="left_forearm_and_palm_assembly">
<visual>
<origin xyz="6.6271857793176427714e-18 0.1062500000000000111 0.00092800153782069891295" rpy="1.570796326794896558 -3.8857805861880478915e-16 -3.141592653589793116" />
<geometry>
<mesh filename="meshes/base_plate.stl"/>
</geometry>
<material name="base_plate_material">
<color rgba="0.91764705882352937127 0.91764705882352937127 0.91764705882352937127 1.0"/>
</material>
</visual>
<collision>
<origin xyz="6.6271857793176427714e-18 0.1062500000000000111 0.00092800153782069891295" rpy="1.570796326794896558 -3.8857805861880478915e-16 -3.141592653589793116" />
<geometry>
<mesh filename="meshes/base_plate.stl"/>
</geometry>
</collision>
<visual>
<origin xyz="6.5458706163812299388e-18 0.10625000000000003886 0.00092800153782067809627" rpy="1.570796326794896558 -3.8857805861880478915e-16 -3.141592653589793116" />
<geometry>
<mesh filename="meshes/forearm_urdf.stl"/>
</geometry>
<material name="forearm_urdf_material">
<color rgba="0.90196078431372550543 0.90196078431372550543 0.90196078431372550543 1.0"/>
</material>
</visual>
<collision>
<origin xyz="6.5458706163812299388e-18 0.10625000000000003886 0.00092800153782067809627" rpy="1.570796326794896558 -3.8857805861880478915e-16 -3.141592653589793116" />
<geometry>
<mesh filename="meshes/forearm_urdf.stl"/>
</geometry>
</collision>
<visual>
<origin xyz="0.093632374404047979954 0.14039834978141413346 0.024699999999999999734" rpy="-1.3877787807814456755e-16 -6.1062266354383619584e-16 3.141592653589793116" />
<geometry>
<mesh filename="meshes/left_palm_urdf.stl"/>
</geometry>
<material name="left_palm_urdf_material">
<color rgba="0.34901960784313723618 0.37647058823529411242 0.4000000000000000222 1.0"/>
</material>
</visual>
<collision>
<origin xyz="0.093632374404047979954 0.14039834978141413346 0.024699999999999999734" rpy="-1.3877787807814456755e-16 -6.1062266354383619584e-16 3.141592653589793116" />
<geometry>
<mesh filename="meshes/left_palm_urdf.stl"/>
</geometry>
</collision>
<inertial>
<origin xyz="0.00052750748368494038316 0.08741215637226693036 -0.001635766870923149657" rpy="0 0 0"/>
<mass value="0.68622918239401642371" />
<inertia ixx="0.0029297962030756905145" ixy="6.2597554394519890723e-06"  ixz="-5.8812781212184875556e-06" iyy="0.00072239266911425497469" iyz="7.8360565756033359261e-05" izz="0.0029586108592181258742" />
</inertial>
</link>

<link name="t4_urdf">
<visual>
<origin xyz="-0.08389999999999996072 1.2143064331837649661e-17 -0.0097499999999999809042" rpy="-3.141592653589793116 -1.5413372953762783163e-17 5.5900639310256326189e-17" />
<geometry>
<mesh filename="meshes/t4_urdf.stl"/>
</geometry>
<material name="t4_urdf_material">
<color rgba="0.34901960784313723618 0.37647058823529411242 0.4000000000000000222 1.0"/>
</material>
</visual>
<collision>
<origin xyz="-0.08389999999999996072 1.2143064331837649661e-17 -0.0097499999999999809042" rpy="-3.141592653589793116 -1.5413372953762783163e-17 5.5900639310256326189e-17" />
<geometry>
<mesh filename="meshes/t4_urdf.stl"/>
</geometry>
</collision>
<inertial>
<origin xyz="-0.0058427530488760759386 -3.1276186823498358798e-10 -0.010494198053015345307" rpy="0 0 0"/>
<mass value="0.010288104754589431911" />
<inertia ixx="9.0136774732367750461e-07" ixy="-8.7726063612149339105e-14"  ixz="1.6540276525723780153e-08" iyy="9.0496845343764967793e-07" iyz="-2.4535322478659827018e-12" izz="1.1625687816350763315e-06" />
</inertial>
</link>

<link name="t3_urdf">
<visual>
<origin xyz="-0.067375000000000032085 -7.5000000000019495516e-05 -0.0087500000000000546091" rpy="-1.5707963267948976682 -5.9811091719746543593e-16 -3.7212248125799093435e-18" />
<geometry>
<mesh filename="meshes/t3_urdf.stl"/>
</geometry>
<material name="t3_urdf_material">
<color rgba="0.34901960784313723618 0.37647058823529411242 0.4000000000000000222 1.0"/>
</material>
</visual>
<collision>
<origin xyz="-0.067375000000000032085 -7.5000000000019495516e-05 -0.0087500000000000546091" rpy="-1.5707963267948976682 -5.9811091719746543593e-16 -3.7212248125799093435e-18" />
<geometry>
<mesh filename="meshes/t3_urdf.stl"/>
</geometry>
</collision>
<inertial>
<origin xyz="-0.00088723630070693115801 -0.014545467252332650726 -0.0087499987535804377853" rpy="0 0 0"/>
<mass value="0.030585609045160683933" />
<inertia ixx="6.360931633969055062e-06" ixy="1.7049934843751153782e-07"  ixz="-5.4125624632162688587e-13" iyy="2.2394270317381832968e-06" iyz="4.5912259697997090719e-13" izz="6.4143771252920703824e-06" />
</inertial>
</link>

<link name="t2_urdf">
<visual>
<origin xyz="-0.067450000000000037703 0.040300000000000030242 -0.0072500000000001053185" rpy="-1.57079632679489678 -1.6518257435107929576e-15 3.661485332619527603e-17" />
<geometry>
<mesh filename="meshes/t2_urdf.stl"/>
</geometry>
<material name="t2_urdf_material">
<color rgba="0.34901960784313723618 0.37647058823529411242 0.4000000000000000222 1.0"/>
</material>
</visual>
<collision>
<origin xyz="-0.067450000000000037703 0.040300000000000030242 -0.0072500000000001053185" rpy="-1.57079632679489678 -1.6518257435107929576e-15 3.661485332619527603e-17" />
<geometry>
<mesh filename="meshes/t2_urdf.stl"/>
</geometry>
</collision>
<inertial>
<origin xyz="0.0091415418957211530548 -0.0010488393377385205052 -0.007249994074379995275" rpy="0 0 0"/>
<mass value="0.014650153995995375544" />
<inertia ixx="7.8231186604803848218e-07" ixy="-1.0095612977356226129e-07"  ixz="-1.4446714870774492365e-13" iyy="1.7012075450960968008e-06" iyz="1.9146942871832067833e-13" izz="1.7152649221551022499e-06" />
</inertial>
</link>

<link name="t1_urdf">
<visual>
<origin xyz="-0.094450000000000006173 0.040300000000000002487 -0.0062500000000000228983" rpy="-1.570796326794896336 -9.1332575962621735714e-16 -5.0643499769007481721e-17" />
<geometry>
<mesh filename="meshes/t1_urdf.stl"/>
</geometry>
<material name="t1_urdf_material">
<color rgba="0.34901960784313723618 0.37647058823529411242 0.4000000000000000222 1.0"/>
</material>
</visual>
<collision>
<origin xyz="-0.094450000000000006173 0.040300000000000002487 -0.0062500000000000228983" rpy="-1.570796326794896336 -9.1332575962621735714e-16 -5.0643499769007481721e-17" />
<geometry>
<mesh filename="meshes/t1_urdf.stl"/>
</geometry>
</collision>
<inertial>
<origin xyz="0.0010824005610938630673 0.010114885903669847828 -0.0062499582332074333016" rpy="0 0 0"/>
<mass value="0.011648615104362203959" />
<inertia ixx="1.0781644849116651883e-06" ixy="2.8463521071566259215e-08"  ixz="-2.6682779313774224007e-12" iyy="4.5092952838938026198e-07" iyz="-5.6995503997945378194e-12" izz="1.1054367169336821178e-06" />
</inertial>
</link>

<joint name="thumb_34" type="revolute">
<origin xyz="0.02699999999999996847 5.5511151231257827021e-17 -0.0010000000000000078271" rpy="3.4009006915900816602e-16 1.5792640726178881672e-15 -1.57079632679489678" />
<parent link="t2_urdf" />
<child link="t1_urdf" />
<axis xyz="0 0 1"/>
<limit effort="1" velocity="20" lower="0" upper="1.570796326794896558"/>
<joint_properties friction="0.0"/>
</joint>

<joint name="thumb_23" type="revolute">
<origin xyz="7.4999999997826805043e-05 -0.04037500000000003586 -0.0015000000000000117406" rpy="6.1081011884469684777e-17 6.564696342128399405e-16 -1.5707963267948970021" />
<parent link="t3_urdf" />
<child link="t2_urdf" />
<axis xyz="0 0 1"/>
<limit effort="1" velocity="20" lower="0" upper="1.570796326794896558"/>
<joint_properties friction="0.0"/>
</joint>

<joint name="thumb_12" type="revolute">
<origin xyz="-0.016524999999999942513 0.0087500000000000147105 -0.0098249999999999448885" rpy="-1.5707963267948956698 -1.2740903539558086077 1.7268164178027235758e-15" />
<parent link="t4_urdf" />
<child link="t3_urdf" />
<axis xyz="0 0 1"/>
<limit effort="1" velocity="20" lower="0.29670597283903604735" upper="1.570796326794896558"/>
<joint_properties friction="0.0"/>
</joint>

<joint name="thumb_01" type="revolute">
<origin xyz="0.014693518066513852616 0.1457335573584342403 -0.026000647022553169396" rpy="1.5707963267948956698 -0.79305228016610029851 -2.9670597283903590302" />
<parent link="left_forearm_and_palm_assembly" />
<child link="t4_urdf" />
<axis xyz="0 0 1"/>
<limit effort="1" velocity="20" lower="-0.785398163397448279" upper="0.785398163397448279"/>
<joint_properties friction="0.0"/>
</joint>

<link name="d4-1_urdf">
<visual>
<origin xyz="-0.079149999999999970379 -3.4694469519536141888e-18 -0.0087500000000000008327" rpy="-3.141592653589793116 2.8217738340531005502e-18 -1.4799331403792561947e-18" />
<geometry>
<mesh filename="meshes/d4-1_urdf.stl"/>
</geometry>
<material name="d4-1_urdf_material">
<color rgba="0.34901960784313723618 0.37647058823529411242 0.4000000000000000222 1.0"/>
</material>
</visual>
<collision>
<origin xyz="-0.079149999999999970379 -3.4694469519536141888e-18 -0.0087500000000000008327" rpy="-3.141592653589793116 2.8217738340531005502e-18 -1.4799331403792561947e-18" />
<geometry>
<mesh filename="meshes/d4-1_urdf.stl"/>
</geometry>
</collision>
<inertial>
<origin xyz="-0.0062842813664121394135 2.5879353408252163504e-10 -0.0081923602347070741819" rpy="0 0 0"/>
<mass value="0.007132231448786834245" />
<inertia ixx="4.8911025414963878454e-07" ixy="-2.0479711681279052493e-14"  ixz="1.435522747422436379e-08" iyy="5.4026894403887874679e-07" iyz="1.5625068492263830404e-13" izz="7.1745332239577878067e-07" />
</inertial>
</link>

<link name="d3-1_urdf">
<visual>
<origin xyz="-0.063875000000000015099 0.0010000000000000008882 -0.0072500000000000480727" rpy="-1.5707963267948976682 -5.938149961013765022e-16 1.9858454729213926187e-18" />
<geometry>
<mesh filename="meshes/d3-1_urdf.stl"/>
</geometry>
<material name="d3-1_urdf_material">
<color rgba="0.34901960784313723618 0.37647058823529411242 0.4000000000000000222 1.0"/>
</material>
</visual>
<collision>
<origin xyz="-0.063875000000000015099 0.0010000000000000008882 -0.0072500000000000480727" rpy="-1.5707963267948976682 -5.938149961013765022e-16 1.9858454729213926187e-18" />
<geometry>
<mesh filename="meshes/d3-1_urdf.stl"/>
</geometry>
</collision>
<inertial>
<origin xyz="-0.00069598131543220631817 -0.01346172837631032064 -0.0072499999060333074341" rpy="0 0 0"/>
<mass value="0.022614819883081289931" />
<inertia ixx="4.0178611346720638305e-06" ixy="1.0347442960778388399e-07"  ixz="1.2277330233914719299e-14" iyy="1.3431972486148475381e-06" iyz="-4.2659478076144771162e-14" izz="4.0893383736852049036e-06" />
</inertial>
</link>

<link name="d2-1_urdf">
<visual>
<origin xyz="-0.062875000000000014211 0.038874999999999999833 -0.0067500000000000927314" rpy="-1.57079632679489678 -1.5959362904671377236e-15 1.772541981320826394e-18" />
<geometry>
<mesh filename="meshes/d2-1_urdf.stl"/>
</geometry>
<material name="d2-1_urdf_material">
<color rgba="0.34901960784313723618 0.37647058823529411242 0.4000000000000000222 1.0"/>
</material>
</visual>
<collision>
<origin xyz="-0.062875000000000014211 0.038874999999999999833 -0.0067500000000000927314" rpy="-1.57079632679489678 -1.5959362904671377236e-15 1.772541981320826394e-18" />
<geometry>
<mesh filename="meshes/d2-1_urdf.stl"/>
</geometry>
</collision>
<inertial>
<origin xyz="0.0084939436722219902043 -0.00026229267814973505901 -0.0067499976398635612093" rpy="0 0 0"/>
<mass value="0.011864989574403397507" />
<inertia ixx="5.4043476975481463473e-07" ixy="-5.8686598046442074273e-08"  ixz="4.1185672850486115445e-14" iyy="1.2212373681404811326e-06" iyz="1.4027559459244865817e-13" izz="1.1986582767037392264e-06" />
</inertial>
</link>

<link name="d1-1_urdf">
<visual>
<origin xyz="-0.088875000000000023426 0.038874999999999937383 -0.0062500000000000194289" rpy="-1.5707963267948961139 -8.9049929426726724149e-16 -2.2178015586428448294e-19" />
<geometry>
<mesh filename="meshes/d1-1_urdf.stl"/>
</geometry>
<material name="d1-1_urdf_material">
<color rgba="0.34901960784313723618 0.37647058823529411242 0.4000000000000000222 1.0"/>
</material>
</visual>
<collision>
<origin xyz="-0.088875000000000023426 0.038874999999999937383 -0.0062500000000000194289" rpy="-1.5707963267948961139 -8.9049929426726724149e-16 -2.2178015586428448294e-19" />
<geometry>
<mesh filename="meshes/d1-1_urdf.stl"/>
</geometry>
</collision>
<inertial>
<origin xyz="0.00081610826597225416285 0.0094232453162033900929 -0.0062500231253482469232" rpy="0 0 0"/>
<mass value="0.0096628566425330745387" />
<inertia ixx="8.369383958001836906e-07" ixy="1.4748701787318227168e-08"  ixz="1.3783262341463528109e-13" iyy="3.1465896345851299994e-07" iyz="2.2310472631963668304e-12" izz="8.3666691222579760474e-07" />
</inertial>
</link>

<joint name="pinky_34" type="revolute">
<origin xyz="0.026000000000000078604 2.5413698923060223933e-16 -0.00050000000000020514146" rpy="-2.6352799622801008862e-16 4.944229418462387411e-15 -1.5707963267948958919" />
<parent link="d2-1_urdf" />
<child link="d1-1_urdf" />
<axis xyz="0 0 1"/>
<limit effort="1" velocity="20" lower="0" upper="1.570796326794896558"/>
<joint_properties friction="0.0"/>
</joint>

<joint name="pinky_23" type="revolute">
<origin xyz="-0.0010000000000001049716 -0.037874999999999880984 -0.00050000000000009411916" rpy="-1.2212476320222462198e-15 4.3296185396076653551e-15 -1.570796326794896336" />
<parent link="d3-1_urdf" />
<child link="d2-1_urdf" />
<axis xyz="0 0 1"/>
<limit effort="1" velocity="20" lower="0" upper="1.570796326794896558"/>
<joint_properties friction="0.0"/>
</joint>

<joint name="pinky_12" type="revolute">
<origin xyz="-0.015275000000000038547 0.0072500000000000792977 -0.0077499999999998108596" rpy="-1.5707963267948972241 -1.5707963267948952257 0" />
<parent link="d4-1_urdf" />
<child link="d3-1_urdf" />
<axis xyz="0 0 1"/>
<limit effort="1" velocity="20" lower="-0.034906585039886590949" upper="1.570796326794896558"/>
<joint_properties friction="0.0"/>
</joint>

<joint name="pinky_01" type="revolute">
<origin xyz="-0.035163940960675876823 0.18909438839224840256 -0.014053824767915700997" rpy="-2.9670597283903603625 -1.5269348559829246889e-15 -1.4791665410651910761" />
<parent link="left_forearm_and_palm_assembly" />
<child link="d4-1_urdf" />
<axis xyz="0 0 1"/>
<limit effort="1" velocity="20" lower="-0.29670597283903604735" upper="0.29670597283903604735"/>
<joint_properties friction="0.0"/>
</joint>

<link name="d4-2_urdf">
<visual>
<origin xyz="-0.079149999999999998135 -2.6020852139652106416e-18 -0.0087499999999999990979" rpy="-3.141592653589793116 5.7436350403613672376e-19 5.7105250889035769782e-18" />
<geometry>
<mesh filename="meshes/d4-2_urdf.stl"/>
</geometry>
<material name="d4-2_urdf_material">
<color rgba="0.34901960784313723618 0.37647058823529411242 0.4000000000000000222 1.0"/>
</material>
</visual>
<collision>
<origin xyz="-0.079149999999999998135 -2.6020852139652106416e-18 -0.0087499999999999990979" rpy="-3.141592653589793116 5.7436350403613672376e-19 5.7105250889035769782e-18" />
<geometry>
<mesh filename="meshes/d4-2_urdf.stl"/>
</geometry>
</collision>
<inertial>
<origin xyz="-0.0062842813664121810469 2.5879353622972663338e-10 -0.0081923602347070724472" rpy="0 0 0"/>
<mass value="0.007132231448786834245" />
<inertia ixx="4.8911025414963857278e-07" ixy="-2.047971166075933831e-14"  ixz="1.4355227474224375371e-08" iyy="5.4026894403887874679e-07" iyz="1.5625068491544848691e-13" izz="7.1745332239577878067e-07" />
</inertial>
</link>

<link name="d3-2_urdf">
<visual>
<origin xyz="-0.063875000000000028977 0.00099999999999994537703 -0.0072500000000000498074" rpy="-1.5707963267948976682 -6.020585537866551411e-16 -4.3503327253986114184e-19" />
<geometry>
<mesh filename="meshes/d3-2_urdf.stl"/>
</geometry>
<material name="d3-2_urdf_material">
<color rgba="0.34901960784313723618 0.37647058823529411242 0.4000000000000000222 1.0"/>
</material>
</visual>
<collision>
<origin xyz="-0.063875000000000028977 0.00099999999999994537703 -0.0072500000000000498074" rpy="-1.5707963267948976682 -6.020585537866551411e-16 -4.3503327253986114184e-19" />
<geometry>
<mesh filename="meshes/d3-2_urdf.stl"/>
</geometry>
</collision>
<inertial>
<origin xyz="-0.00069598131543222030437 -0.013461728376310377886 -0.0072499999060333074341" rpy="0 0 0"/>
<mass value="0.0226148198830812934" />
<inertia ixx="4.0178611346720646775e-06" ixy="1.0347442960778385752e-07"  ixz="1.2277330187828540671e-14" iyy="1.3431972486148477499e-06" iyz="-4.2659478036138409795e-14" izz="4.0893383736852091388e-06" />
</inertial>
</link>

<link name="d2-2_urdf">
<visual>
<origin xyz="-0.062875000000000014211 0.038875000000000013711 -0.0067500000000000962008" rpy="-1.570796326794896558 -1.6154086291802975957e-15 4.0910723722577696972e-19" />
<geometry>
<mesh filename="meshes/d2-2_urdf.stl"/>
</geometry>
<material name="d2-2_urdf_material">
<color rgba="0.34901960784313723618 0.37647058823529411242 0.4000000000000000222 1.0"/>
</material>
</visual>
<collision>
<origin xyz="-0.062875000000000014211 0.038875000000000013711 -0.0067500000000000962008" rpy="-1.570796326794896558 -1.6154086291802975957e-15 4.0910723722577696972e-19" />
<geometry>
<mesh filename="meshes/d2-2_urdf.stl"/>
</geometry>
</collision>
<inertial>
<origin xyz="0.0084939436722219485709 -0.00026229267814972812012 -0.0067499976398635646788" rpy="0 0 0"/>
<mass value="0.011864989574403399242" />
<inertia ixx="5.4043476975481442297e-07" ixy="-5.8686598046442061038e-08"  ixz="4.1185672837476600049e-14" iyy="1.2212373681404815561e-06" iyz="1.4027559471491970498e-13" izz="1.1986582767037388029e-06" />
</inertial>
</link>

<link name="d1-2_urdf">
<visual>
<origin xyz="-0.088875000000000023426 0.038874999999999992895 -0.00625000000000001249" rpy="-1.5707963267948961139 -8.7617542712142407905e-16 -2.563173964937819768e-19" />
<geometry>
<mesh filename="meshes/d1-2_urdf.stl"/>
</geometry>
<material name="d1-2_urdf_material">
<color rgba="0.34901960784313723618 0.37647058823529411242 0.4000000000000000222 1.0"/>
</material>
</visual>
<collision>
<origin xyz="-0.088875000000000023426 0.038874999999999992895 -0.00625000000000001249" rpy="-1.5707963267948961139 -8.7617542712142407905e-16 -2.563173964937819768e-19" />
<geometry>
<mesh filename="meshes/d1-2_urdf.stl"/>
</geometry>
</collision>
<inertial>
<origin xyz="0.00081610826597225405443 0.009423245316203445604 -0.0062500231253482399843" rpy="0 0 0"/>
<mass value="0.009662856642533072804" />
<inertia ixx="8.369383958001836906e-07" ixy="1.4748701787318213933e-08"  ixz="1.3783262334413317902e-13" iyy="3.1465896345851299994e-07" iyz="2.2310472631938477262e-12" izz="8.3666691222579760474e-07" />
</inertial>
</link>

<joint name="ring_34" type="revolute">
<origin xyz="0.025999999999999967581 -3.1035287187397564423e-18 -0.00050000000000005768996" rpy="-7.9116884346704368568e-16 -8.8844589975538007006e-17 -1.570796326794961173" />
<parent link="d2-2_urdf" />
<child link="d1-2_urdf" />
<axis xyz="0 0 1"/>
<limit effort="1" velocity="20" lower="0" upper="1.570796326794896558"/>
<joint_properties friction="0.0"/>
</joint>

<joint name="ring_23" type="revolute">
<origin xyz="-0.0010000000000000579172 -0.037875000000000103029 -0.00049999999999996574962" rpy="-6.6268267847551512137e-16 -1.0385351093495972025e-15 -1.570796326794896336" />
<parent link="d3-2_urdf" />
<child link="d2-2_urdf" />
<axis xyz="0 0 1"/>
<limit effort="1" velocity="20" lower="0" upper="1.570796326794896558"/>
<joint_properties friction="0.0"/>
</joint>

<joint name="ring_12" type="revolute">
<origin xyz="-0.015274999999999983036 0.007250000000000039399 -0.0077499999999999522396" rpy="-1.570796326794896558 -1.5707963267948961139 0" />
<parent link="d4-2_urdf" />
<child link="d3-2_urdf" />
<axis xyz="0 0 1"/>
<limit effort="1" velocity="20" lower="-0.034906585039886590949" upper="1.570796326794896558"/>
<joint_properties friction="0.0"/>
</joint>

<joint name="ring_01" type="revolute">
<origin xyz="-0.011784350148794277974 0.19516197601440893328 -0.01051396557923191255" rpy="-3.0545918230670441318 -0.0068123514634775093196 -1.5321205940965847425" />
<parent link="left_forearm_and_palm_assembly" />
<child link="d4-2_urdf" />
<axis xyz="0 0 1"/>
<limit effort="1" velocity="20" lower="-0.29670597283903604735" upper="0.29670597283903604735"/>
<joint_properties friction="0.0"/>
</joint>

<link name="d4-3_urdf">
<visual>
<origin xyz="-0.079149999999999970379 1.7347234759768070944e-18 -0.0087499999999999990979" rpy="-3.141592653589793116 -2.6325985379695400651e-32 9.8865196963416920084e-33" />
<geometry>
<mesh filename="meshes/d4-3_urdf.stl"/>
</geometry>
<material name="d4-3_urdf_material">
<color rgba="0.34901960784313723618 0.37647058823529411242 0.4000000000000000222 1.0"/>
</material>
</visual>
<collision>
<origin xyz="-0.079149999999999970379 1.7347234759768070944e-18 -0.0087499999999999990979" rpy="-3.141592653589793116 -2.6325985379695400651e-32 9.8865196963416920084e-33" />
<geometry>
<mesh filename="meshes/d4-3_urdf.stl"/>
</geometry>
</collision>
<inertial>
<origin xyz="-0.0062842813664121394135 2.5879353945960150382e-10 -0.0081923602347070724472" rpy="0 0 0"/>
<mass value="0.0071322314487868333777" />
<inertia ixx="4.8911025414963878454e-07" ixy="-2.0479711693406523578e-14"  ixz="1.4355227474224378679e-08" iyy="5.4026894403887853503e-07" iyz="1.5625068491580689482e-13" izz="7.1745332239577867479e-07" />
</inertial>
</link>

<link name="d3-3_urdf">
<visual>
<origin xyz="-0.063875000000000015099 0.0009999999999999731326 -0.0072500000000000480727" rpy="-1.5707963267948976682 -5.8880953492685354486e-16 9.2444637330576646994e-33" />
<geometry>
<mesh filename="meshes/d3-3_urdf.stl"/>
</geometry>
<material name="d3-3_urdf_material">
<color rgba="0.34901960784313723618 0.37647058823529411242 0.4000000000000000222 1.0"/>
</material>
</visual>
<collision>
<origin xyz="-0.063875000000000015099 0.0009999999999999731326 -0.0072500000000000480727" rpy="-1.5707963267948976682 -5.8880953492685354486e-16 9.2444637330576646994e-33" />
<geometry>
<mesh filename="meshes/d3-3_urdf.stl"/>
</geometry>
</collision>
<inertial>
<origin xyz="-0.00069598131543220631817 -0.013461728376310346661 -0.0072499999060333074341" rpy="0 0 0"/>
<mass value="0.022614819883081289931" />
<inertia ixx="4.0178611346720655246e-06" ixy="1.0347442960778381782e-07"  ixz="1.2277330139237473078e-14" iyy="1.3431972486148479617e-06" iyz="-4.2659478051237800744e-14" izz="4.0893383736852065977e-06" />
</inertial>
</link>

<link name="d2-3_urdf">
<visual>
<origin xyz="-0.062874999999999986455 0.038874999999999999833 -0.0067500000000000944661" rpy="-1.57079632679489678 -1.6156388965885129953e-15 3.6977854932234928379e-32" />
<geometry>
<mesh filename="meshes/d2-3_urdf.stl"/>
</geometry>
<material name="d2-3_urdf_material">
<color rgba="0.34901960784313723618 0.37647058823529411242 0.4000000000000000222 1.0"/>
</material>
</visual>
<collision>
<origin xyz="-0.062874999999999986455 0.038874999999999999833 -0.0067500000000000944661" rpy="-1.57079632679489678 -1.6156388965885129953e-15 3.6977854932234928379e-32" />
<geometry>
<mesh filename="meshes/d2-3_urdf.stl"/>
</geometry>
</collision>
<inertial>
<origin xyz="0.0084939436722220040821 -0.00026229267814974199791 -0.0067499976398635620767" rpy="0 0 0"/>
<mass value="0.011864989574403397507" />
<inertia ixx="5.4043476975481452885e-07" ixy="-5.868659804644208089e-08"  ixz="4.1185672877430025694e-14" iyy="1.2212373681404815561e-06" iyz="1.4027559464644640171e-13" izz="1.1986582767037392264e-06" />
</inertial>
</link>

<link name="d1-3_urdf">
<visual>
<origin xyz="-0.088875000000000009548 0.038874999999999937383 -0.0062500000000000107553" rpy="-1.5707963267948961139 -8.7170368868848025935e-16 2.7733391199175887998e-30" />
<geometry>
<mesh filename="meshes/d1-3_urdf.stl"/>
</geometry>
<material name="d1-3_urdf_material">
<color rgba="0.34901960784313723618 0.37647058823529411242 0.4000000000000000222 1.0"/>
</material>
</visual>
<collision>
<origin xyz="-0.088875000000000009548 0.038874999999999937383 -0.0062500000000000107553" rpy="-1.5707963267948961139 -8.7170368868848025935e-16 2.7733391199175887998e-30" />
<geometry>
<mesh filename="meshes/d1-3_urdf.stl"/>
</geometry>
</collision>
<inertial>
<origin xyz="0.00081610826597226793222 0.0094232453162033900929 -0.0062500231253482408517" rpy="0 0 0"/>
<mass value="0.0096628566425330745387" />
<inertia ixx="8.369383958001836906e-07" ixy="1.474870178731823544e-08"  ixz="1.378326234100062453e-13" iyy="3.1465896345851299994e-07" iyz="2.2310472631899682976e-12" izz="8.3666691222579718122e-07" />
</inertial>
</link>

<joint name="middle_34" type="revolute">
<origin xyz="0.026000000000000134115 -4.5536491244391186228e-18 -0.00050000000000000044409" rpy="-2.9646186017117878309e-15 3.6635847905925687338e-16 -1.5707963267948532593" />
<parent link="d2-3_urdf" />
<child link="d1-3_urdf" />
<axis xyz="0 0 1"/>
<limit effort="1" velocity="20" lower="0" upper="1.570796326794896558"/>
<joint_properties friction="0.0"/>
</joint>

<joint name="middle_23" type="revolute">
<origin xyz="-0.001000000000000215777 -0.037874999999999825473 -0.00050000000000005248579" rpy="-1.0155656137714762e-15 -8.1269680571163029421e-16 -1.5707963267948970021" />
<parent link="d3-3_urdf" />
<child link="d2-3_urdf" />
<axis xyz="0 0 1"/>
<limit effort="1" velocity="20" lower="0" upper="1.570796326794896558"/>
<joint_properties friction="0.0"/>
</joint>

<joint name="middle_12" type="revolute">
<origin xyz="-0.015275000000000010791 0.0072500000000000402664 -0.0077499999999999453007" rpy="-1.57079632679489678 -1.5707963267948961139 0" />
<parent link="d4-3_urdf" />
<child link="d3-3_urdf" />
<axis xyz="0 0 1"/>
<limit effort="1" velocity="20" lower="-0.034906585039886590949" upper="1.570796326794896558"/>
<joint_properties friction="0.0"/>
</joint>

<joint name="middle_01" type="revolute">
<origin xyz="0.011738453089343185015 0.19915000000000054881 -0.0080006470225532679008" rpy="3.1415926535897926719 1.307825854535432319e-16 -1.57079632679489678" />
<parent link="left_forearm_and_palm_assembly" />
<child link="d4-3_urdf" />
<axis xyz="0 0 1"/>
<limit effort="1" velocity="20" lower="-0.29670597283903604735" upper="0.29670597283903604735"/>
<joint_properties friction="0.0"/>
</joint>

<link name="d4-4_urdf">
<visual>
<origin xyz="-0.079149999999999942624 0 -0.0087500000000000025674" rpy="3.141592653589793116 4.0724214608378616298e-19 9.955054590212099495e-19" />
<geometry>
<mesh filename="meshes/d4-4_urdf.stl"/>
</geometry>
<material name="d4-4_urdf_material">
<color rgba="0.34901960784313723618 0.37647058823529411242 0.4000000000000000222 1.0"/>
</material>
</visual>
<collision>
<origin xyz="-0.079149999999999942624 0 -0.0087500000000000025674" rpy="3.141592653589793116 4.0724214608378616298e-19 9.955054590212099495e-19" />
<geometry>
<mesh filename="meshes/d4-4_urdf.stl"/>
</geometry>
</collision>
<inertial>
<origin xyz="-0.0062842813664121255357 2.5879353670207297444e-10 -0.0081923602347070759166" rpy="0 0 0"/>
<mass value="0.007132231448786834245" />
<inertia ixx="4.8911025414963857278e-07" ixy="-2.0479711720231416805e-14"  ixz="1.4355227474224372062e-08" iyy="5.4026894403887874679e-07" iyz="1.5625068491312486871e-13" izz="7.1745332239577878067e-07" />
</inertial>
</link>

<link name="d3-4_urdf">
<visual>
<origin xyz="-0.063875000000000001221 0.0010000000000000008882 -0.0072500000000000480727" rpy="-1.5707963267948976682 -5.8599645083033892048e-16 -1.0864206181267581595e-18" />
<geometry>
<mesh filename="meshes/d3-4_urdf.stl"/>
</geometry>
<material name="d3-4_urdf_material">
<color rgba="0.34901960784313723618 0.37647058823529411242 0.4000000000000000222 1.0"/>
</material>
</visual>
<collision>
<origin xyz="-0.063875000000000001221 0.0010000000000000008882 -0.0072500000000000480727" rpy="-1.5707963267948976682 -5.8599645083033892048e-16 -1.0864206181267581595e-18" />
<geometry>
<mesh filename="meshes/d3-4_urdf.stl"/>
</geometry>
</collision>
<inertial>
<origin xyz="-0.0006959813154321925488 -0.01346172837631032064 -0.0072499999060333074341" rpy="0 0 0"/>
<mass value="0.022614819883081289931" />
<inertia ixx="4.0178611346719537162e-06" ixy="1.0347442960778401634e-07"  ixz="1.2277290902497269552e-14" iyy="1.3431972486147585997e-06" iyz="-4.2659478046458717297e-14" izz="4.0893383736852303146e-06" />
</inertial>
</link>

<link name="d2-4_urdf">
<visual>
<origin xyz="-0.0628749999999999587 0.038875000000000006772 -0.0067500000000001031397" rpy="-1.57079632679489678 -1.6210129897967071333e-15 -1.2557336324437900059e-19" />
<geometry>
<mesh filename="meshes/d2-4_urdf.stl"/>
</geometry>
<material name="d2-4_urdf_material">
<color rgba="0.34901960784313723618 0.37647058823529411242 0.4000000000000000222 1.0"/>
</material>
</visual>
<collision>
<origin xyz="-0.0628749999999999587 0.038875000000000006772 -0.0067500000000001031397" rpy="-1.57079632679489678 -1.6210129897967071333e-15 -1.2557336324437900059e-19" />
<geometry>
<mesh filename="meshes/d2-4_urdf.stl"/>
</geometry>
</collision>
<inertial>
<origin xyz="0.0084939436722220179599 -0.00026229267814973505901 -0.0067499976398635707503" rpy="0 0 0"/>
<mass value="0.011864989574403399242" />
<inertia ixx="5.4043476975481452885e-07" ixy="-5.868659804644208089e-08"  ixz="4.1185672843456538053e-14" iyy="1.2212373681404815561e-06" iyz="1.4027559465987518721e-13" izz="1.1986582767037390146e-06" />
</inertial>
</link>

<link name="d1-4_urdf">
<visual>
<origin xyz="-0.088875000000000023426 0.038874999999999992895 -0.00625000000000001249" rpy="-1.5707963267948961139 -8.8313615935463643366e-16 -2.1605675056595369633e-20" />
<geometry>
<mesh filename="meshes/d1-4_urdf.stl"/>
</geometry>
<material name="d1-4_urdf_material">
<color rgba="0.34901960784313723618 0.37647058823529411242 0.4000000000000000222 1.0"/>
</material>
</visual>
<collision>
<origin xyz="-0.088875000000000023426 0.038874999999999992895 -0.00625000000000001249" rpy="-1.5707963267948961139 -8.8313615935463643366e-16 -2.1605675056595369633e-20" />
<geometry>
<mesh filename="meshes/d1-4_urdf.stl"/>
</geometry>
</collision>
<inertial>
<origin xyz="0.00081610826597225405443 0.009423245316203445604 -0.0062500231253482399843" rpy="0 0 0"/>
<mass value="0.009662856642533072804" />
<inertia ixx="8.369383958001836906e-07" ixy="1.4748701787318237094e-08"  ixz="1.3783262333893621387e-13" iyy="3.1465896345851299994e-07" iyz="2.2310472631903451333e-12" izz="8.3666691222579696946e-07" />
</inertial>
</link>

<joint name="index_34" type="revolute">
<origin xyz="0.026000000000000050848 -5.0957502106818708398e-18 -0.00049999999999996574962" rpy="1.4027645268064363647e-15 -2.2530004780047258679e-15 -1.57079632679489678" />
<parent link="d2-4_urdf" />
<child link="d1-4_urdf" />
<axis xyz="0 0 1"/>
<limit effort="1" velocity="20" lower="0" upper="1.570796326794896558"/>
<joint_properties friction="0.0"/>
</joint>

<joint name="index_23" type="revolute">
<origin xyz="-0.0010000000000000412205 -0.037874999999999964251 -0.00050000000000011840529" rpy="-2.4817590593525338253e-15 2.570777650635345777e-15 -1.5707963267948958919" />
<parent link="d3-4_urdf" />
<child link="d2-4_urdf" />
<axis xyz="0 0 1"/>
<limit effort="1" velocity="20" lower="0" upper="1.570796326794896558"/>
<joint_properties friction="0.0"/>
</joint>

<joint name="index_12" type="revolute">
<origin xyz="-0.015274999999999872013 0.0072500000000000966449 -0.0077499999999998967284" rpy="-1.5707963267948976682 -1.5707963267948830133 0" />
<parent link="d4-4_urdf" />
<child link="d3-4_urdf" />
<axis xyz="0 0 1"/>
<limit effort="1" velocity="20" lower="-0.034906585039886590949" upper="1.570796326794896558"/>
<joint_properties friction="0.0"/>
</joint>

<joint name="index_01" type="revolute">
<origin xyz="0.0352612563274789792 0.19513802398559310092 -0.010513965579231661016" rpy="3.0543261909900740747 -2.6020852139652102472e-15 -1.6100662349647958393" />
<parent link="left_forearm_and_palm_assembly" />
<child link="d4-4_urdf" />
<axis xyz="0 0 1"/>
<limit effort="1" velocity="20" lower="-0.29670597283903604735" upper="0.29670597283903604735"/>
<joint_properties friction="0.0"/>
</joint>


</robot>
