<robot name="ArtusLite_RightHand">


    <link name="base_link"/>
    <joint name="r_virtual" type="fixed">
    <origin xyz="0 0 0" rpy="1.67 0 0"/>
    <parent link="base_link"/>
    <child link="right_forearm_and_palm_assembly"/>
    </joint>

<link name="right_forearm_and_palm_assembly">
<visual>
<origin xyz="-1.7347234759768070944e-18 0.1062500000000000111 -0.00092800153782063960709" rpy="-1.570796326794896558 -0 0" />
<geometry>
<mesh filename="meshes/forearm_urdf.stl"/>
</geometry>
<material name="forearm_urdf_material">
<color rgba="0.90196078431372550543 0.90196078431372550543 0.90196078431372550543 1.0"/>
</material>
</visual>
<collision>
<origin xyz="-1.7347234759768070944e-18 0.1062500000000000111 -0.00092800153782063960709" rpy="-1.570796326794896558 -0 0" />
<geometry>
<mesh filename="meshes/forearm_urdf.stl"/>
</geometry>
</collision>
<visual>
<origin xyz="-2.5931183038634623242e-18 0.10624999999999998335 -0.00092800153782065695433" rpy="-1.570796326794896558 -0 0" />
<geometry>
<mesh filename="meshes/base_plate.stl"/>
</geometry>
<material name="base_plate_material">
<color rgba="0.91764705882352937127 0.91764705882352937127 0.91764705882352937127 1.0"/>
</material>
</visual>
<collision>
<origin xyz="-2.5931183038634623242e-18 0.10624999999999998335 -0.00092800153782065695433" rpy="-1.570796326794896558 -0 0" />
<geometry>
<mesh filename="meshes/base_plate.stl"/>
</geometry>
</collision>
<visual>
<origin xyz="0.020167625595952053119 0.14039834978141407795 -0.024699999999999965039" rpy="-3.141592653589793116 4.107269014279329376e-28 5.551115123168064414e-17" />
<geometry>
<mesh filename="meshes/right_palm_urdf.stl"/>
</geometry>
<material name="right_palm_urdf_material">
<color rgba="0.34901960784313723618 0.37647058823529411242 0.4000000000000000222 1.0"/>
</material>
</visual>
<collision>
<origin xyz="0.020167625595952053119 0.14039834978141407795 -0.024699999999999965039" rpy="-3.141592653589793116 4.107269014279329376e-28 5.551115123168064414e-17" />
<geometry>
<mesh filename="meshes/right_palm_urdf.stl"/>
</geometry>
</collision>
<inertial>
<origin xyz="-0.00031902366677876852234 0.087412368889735150845 0.0016356295512675925446" rpy="0 0 0"/>
<mass value="0.68623229347541214729" />
<inertia ixx="0.0029298018982895296727" ixy="-3.2787714570297250589e-05"  ixz="7.49398691163713417e-06" iyy="0.00072251879264721209119" iyz="-7.8355795079132581783e-05" izz="0.0029587437073185559461" />
</inertial>
</link>

<link name="t4_urdf">
<visual>
<origin xyz="-0.083899999999999974598 1.561251128379126385e-17 -0.0097499999999999809042" rpy="3.141592653589793116 -1.2794653093373542632e-18 -3.2844435264478311648e-17" />
<geometry>
<mesh filename="meshes/t4_urdf.stl"/>
</geometry>
<material name="t4_urdf_material">
<color rgba="0.34901960784313723618 0.37647058823529411242 0.4000000000000000222 1.0"/>
</material>
</visual>
<collision>
<origin xyz="-0.083899999999999974598 1.561251128379126385e-17 -0.0097499999999999809042" rpy="3.141592653589793116 -1.2794653093373542632e-18 -3.2844435264478311648e-17" />
<geometry>
<mesh filename="meshes/t4_urdf.stl"/>
</geometry>
</collision>
<inertial>
<origin xyz="-0.0058427530488760759386 -3.1276187171275647469e-10 -0.010494198053015347041" rpy="0 0 0"/>
<mass value="0.010288104754589431911" />
<inertia ixx="9.0136774732367771637e-07" ixy="-8.7726063657798889533e-14"  ixz="1.6540276525723776845e-08" iyy="9.0496845343764967793e-07" iyz="-2.4535322478506043318e-12" izz="1.162568781635075908e-06" />
</inertial>
</link>

<link name="t3_urdf">
<visual>
<origin xyz="-0.06737500000000000433 -7.5000000000019495516e-05 -0.0087500000000000528744" rpy="-1.5707963267948976682 -6.2308664708005556299e-16 6.9434614612816685322e-17" />
<geometry>
<mesh filename="meshes/t3_urdf.stl"/>
</geometry>
<material name="t3_urdf_material">
<color rgba="0.34901960784313723618 0.37647058823529411242 0.4000000000000000222 1.0"/>
</material>
</visual>
<collision>
<origin xyz="-0.06737500000000000433 -7.5000000000019495516e-05 -0.0087500000000000528744" rpy="-1.5707963267948976682 -6.2308664708005556299e-16 6.9434614612816685322e-17" />
<geometry>
<mesh filename="meshes/t3_urdf.stl"/>
</geometry>
</collision>
<inertial>
<origin xyz="-0.00088723630070688952465 -0.014545467252332643787 -0.0087499987535804360506" rpy="0 0 0"/>
<mass value="0.030585609045160683933" />
<inertia ixx="6.360931633969056756e-06" ixy="1.7049934843751185546e-07"  ixz="-5.41256245982849573e-13" iyy="2.2394270317381824498e-06" iyz="4.5912259846715935459e-13" izz="6.4143771252920686883e-06" />
</inertial>
</link>

<link name="t2_urdf">
<visual>
<origin xyz="-0.067450000000000023825 0.040300000000000030242 -0.0072500000000001018491" rpy="-1.570796326794896558 -1.5517967110789131212e-15 -6.3719847758218301958e-17" />
<geometry>
<mesh filename="meshes/t2_urdf.stl"/>
</geometry>
<material name="t2_urdf_material">
<color rgba="0.34901960784313723618 0.37647058823529411242 0.4000000000000000222 1.0"/>
</material>
</visual>
<collision>
<origin xyz="-0.067450000000000023825 0.040300000000000030242 -0.0072500000000001018491" rpy="-1.570796326794896558 -1.5517967110789131212e-15 -6.3719847758218301958e-17" />
<geometry>
<mesh filename="meshes/t2_urdf.stl"/>
</geometry>
</collision>
<inertial>
<origin xyz="0.0091415418957211808104 -0.0010488393377385274441 -0.0072499940743799996118" rpy="0 0 0"/>
<mass value="0.014650153995995375544" />
<inertia ixx="7.8231186604803869393e-07" ixy="-1.009561297735623407e-07"  ixz="-1.4446714839154955568e-13" iyy="1.7012075450960968008e-06" iyz="1.9146942865674886037e-13" izz="1.7152649221551014029e-06" />
</inertial>
</link>

<link name="t1_urdf">
<visual>
<origin xyz="-0.094450000000000075562 0.040299999999999974731 -0.0062500000000000263678" rpy="-1.5707963267948961139 -9.7518361293170801771e-16 -3.0377457227063286795e-18" />
<geometry>
<mesh filename="meshes/t1_urdf.stl"/>
</geometry>
<material name="t1_urdf_material">
<color rgba="0.34901960784313723618 0.37647058823529411242 0.4000000000000000222 1.0"/>
</material>
</visual>
<collision>
<origin xyz="-0.094450000000000075562 0.040299999999999974731 -0.0062500000000000263678" rpy="-1.5707963267948961139 -9.7518361293170801771e-16 -3.0377457227063286795e-18" />
<geometry>
<mesh filename="meshes/t1_urdf.stl"/>
</geometry>
</collision>
<inertial>
<origin xyz="0.0010824005610937936783 0.010114885903669816603 -0.0062499582332074333016" rpy="0 0 0"/>
<mass value="0.011648615104362203959" />
<inertia ixx="1.0781644849116651883e-06" ixy="2.8463521071566308846e-08"  ixz="-2.6682779313437515453e-12" iyy="4.5092952838938047374e-07" iyz="-5.6995503998901272633e-12" izz="1.1054367169336816943e-06" />
</inertial>
</link>

<joint name="thumb_34" type="revolute">
<origin xyz="0.02699999999999996847 -4.1633363423443370266e-17 -0.0010000000000000286438" rpy="2.0108136658001474543e-14 -1.3535182064577502269e-14 -1.57079632679489678" />
<parent link="t2_urdf" />
<child link="t1_urdf" />
<axis xyz="0 0 1"/>
<limit effort="1" velocity="20" lower="0" upper="1.570796326794896558"/>
<joint_properties friction="0.0"/>
</joint>

<joint name="thumb_23" type="revolute">
<origin xyz="7.4999999999450506216e-05 -0.040374999999997690514 -0.0015000000000003914282" rpy="1.5022520038205650076e-14 2.0353434029585057533e-14 -1.5707963267948945596" />
<parent link="t3_urdf" />
<child link="t2_urdf" />
<axis xyz="0 0 1"/>
<limit effort="1" velocity="20" lower="0" upper="1.570796326794896558"/>
<joint_properties friction="0.0"/>
</joint>

<joint name="thumb_12" type="revolute">
<origin xyz="-0.016524999999999866185 0.0087500000000000511396 -0.0098249999999993342659" rpy="-1.570796326794901443 -1.2740903539558616764 -4.5001425164792760456e-15" />
<parent link="t4_urdf" />
<child link="t3_urdf" />
<axis xyz="0 0 1"/>
<limit effort="1" velocity="20" lower="0.29670597283903604735" upper="1.570796326794896558"/>
<joint_properties friction="0.0"/>
</joint>

<joint name="thumb_01" type="revolute">
<origin xyz="0.014693521091338347662 0.14573355735843276926 0.026000647022553294296" rpy="1.5707963267948972241 0.79305228016606710284 -2.9670597283903594743" />
<parent link="right_forearm_and_palm_assembly" />
<child link="t4_urdf" />
<axis xyz="0 0 1"/>
<limit effort="1" velocity="20" lower="-0.785398163397448279" upper="0.785398163397448279"/>
<joint_properties friction="0.0"/>
</joint>

<link name="d4-1_urdf">
<visual>
<origin xyz="-0.07915000000000002589 -3.4694469519536141888e-18 -0.0087500000000000008327" rpy="-3.141592653589793116 -7.4443567559721403992e-19 1.0353695998231723084e-17" />
<geometry>
<mesh filename="meshes/d4-1_urdf.stl"/>
</geometry>
<material name="d4-1_urdf_material">
<color rgba="0.34901960784313723618 0.37647058823529411242 0.4000000000000000222 1.0"/>
</material>
</visual>
<collision>
<origin xyz="-0.07915000000000002589 -3.4694469519536141888e-18 -0.0087500000000000008327" rpy="-3.141592653589793116 -7.4443567559721403992e-19 1.0353695998231723084e-17" />
<geometry>
<mesh filename="meshes/d4-1_urdf.stl"/>
</geometry>
</collision>
<inertial>
<origin xyz="-0.0062842813664121949246 2.587935349302326119e-10 -0.0081923602347070741819" rpy="0 0 0"/>
<mass value="0.007132231448786834245" />
<inertia ixx="4.8911025414963878454e-07" ixy="-2.0479711687832167364e-14"  ixz="1.4355227474224367099e-08" iyy="5.4026894403887874679e-07" iyz="1.5625068491530810753e-13" izz="7.1745332239577878067e-07" />
</inertial>
</link>

<link name="d3-1_urdf">
<visual>
<origin xyz="-0.063875000000000001221 0.0010000000000000008882 -0.0072500000000000480727" rpy="-1.5707963267948976682 -5.8030354937565350676e-16 2.0073644290647640091e-18" />
<geometry>
<mesh filename="meshes/d3-1_urdf.stl"/>
</geometry>
<material name="d3-1_urdf_material">
<color rgba="0.34901960784313723618 0.37647058823529411242 0.4000000000000000222 1.0"/>
</material>
</visual>
<collision>
<origin xyz="-0.063875000000000001221 0.0010000000000000008882 -0.0072500000000000480727" rpy="-1.5707963267948976682 -5.8030354937565350676e-16 2.0073644290647640091e-18" />
<geometry>
<mesh filename="meshes/d3-1_urdf.stl"/>
</geometry>
</collision>
<inertial>
<origin xyz="-0.0006959813154321925488 -0.01346172837631032064 -0.0072499999060333091688" rpy="0 0 0"/>
<mass value="0.022614819883081289931" />
<inertia ixx="4.0178611346720638305e-06" ixy="1.0347442960778388399e-07"  ixz="1.2277330175343376386e-14" iyy="1.3431972486148475381e-06" iyz="-4.2659478099691568674e-14" izz="4.0893383736852065977e-06" />
</inertial>
</link>

<link name="d2-1_urdf">
<visual>
<origin xyz="-0.062874999999999986455 0.038875000000000006772 -0.0067500000000000840578" rpy="-1.57079632679489678 -1.5927435854182864622e-15 -3.5942939148162164478e-18" />
<geometry>
<mesh filename="meshes/d2-1_urdf.stl"/>
</geometry>
<material name="d2-1_urdf_material">
<color rgba="0.34901960784313723618 0.37647058823529411242 0.4000000000000000222 1.0"/>
</material>
</visual>
<collision>
<origin xyz="-0.062874999999999986455 0.038875000000000006772 -0.0067500000000000840578" rpy="-1.57079632679489678 -1.5927435854182864622e-15 -3.5942939148162164478e-18" />
<geometry>
<mesh filename="meshes/d2-1_urdf.stl"/>
</geometry>
</collision>
<inertial>
<origin xyz="0.0084939436722219902043 -0.00026229267814973505901 -0.0067499976398635534031" rpy="0 0 0"/>
<mass value="0.011864989574403397507" />
<inertia ixx="5.4043476975481421121e-07" ixy="-5.8686598046442061038e-08"  ixz="4.1185672873849638481e-14" iyy="1.2212373681404815561e-06" iyz="1.4027559460025386254e-13" izz="1.1986582767037392264e-06" />
</inertial>
</link>

<link name="d1-1_urdf">
<visual>
<origin xyz="-0.088875000000000009548 0.038874999999999992895 -0.0062500000000000142247" rpy="-1.5707963267948961139 -8.5497560105453835645e-16 -2.3624031506968628575e-18" />
<geometry>
<mesh filename="meshes/d1-1_urdf.stl"/>
</geometry>
<material name="d1-1_urdf_material">
<color rgba="0.34901960784313723618 0.37647058823529411242 0.4000000000000000222 1.0"/>
</material>
</visual>
<collision>
<origin xyz="-0.088875000000000009548 0.038874999999999992895 -0.0062500000000000142247" rpy="-1.5707963267948961139 -8.5497560105453835645e-16 -2.3624031506968628575e-18" />
<geometry>
<mesh filename="meshes/d1-1_urdf.stl"/>
</geometry>
</collision>
<inertial>
<origin xyz="0.00081610826597225416285 0.009423245316203445604 -0.0062500231253482451885" rpy="0 0 0"/>
<mass value="0.0096628566425330745387" />
<inertia ixx="8.3693839580018347884e-07" ixy="1.4748701787318223859e-08"  ixz="1.3783262336749696712e-13" iyy="3.1465896345851299994e-07" iyz="2.2310472631993794965e-12" izz="8.3666691222579718122e-07" />
</inertial>
</link>

<joint name="pinky_34" type="revolute">
<origin xyz="0.025999999999999967581 -4.7704895589362195096e-18 -0.00049999999999998136213" rpy="5.0133770924262931337e-15 1.4789047887596532477e-15 -1.5707963267948970021" />
<parent link="d2-1_urdf" />
<child link="d1-1_urdf" />
<axis xyz="0 0 1"/>
<limit effort="1" velocity="20" lower="0" upper="1.570796326794896558"/>
<joint_properties friction="0.0"/>
</joint>

<joint name="pinky_23" type="revolute">
<origin xyz="-0.0010000000000003552054 -0.037875000000000297318 -0.00049999999999856582777" rpy="-2.7917766663472194013e-15 -4.5153227605194488046e-15 -1.5707963267948992225" />
<parent link="d3-1_urdf" />
<child link="d2-1_urdf" />
<axis xyz="0 0 1"/>
<limit effort="1" velocity="20" lower="0" upper="1.570796326794896558"/>
<joint_properties friction="0.0"/>
</joint>

<joint name="pinky_12" type="revolute">
<origin xyz="-0.015275000000000121814 0.0072500000000001157269 -0.0077499999999997119804" rpy="-1.5707963267948918951 -1.5707963267948952257 0" />
<parent link="d4-1_urdf" />
<child link="d3-1_urdf" />
<axis xyz="0 0 1"/>
<limit effort="1" velocity="20" lower="-0.034906585039886590949" upper="1.570796326794896558"/>
<joint_properties friction="0.0"/>
</joint>

<joint name="pinky_01" type="revolute">
<origin xyz="-0.035163937935848779692 0.18909438839224823603 0.014053824767915794672" rpy="-0.17453292519943353067 1.1456913421203554045e-15 -1.4791665410651946289" />
<parent link="right_forearm_and_palm_assembly" />
<child link="d4-1_urdf" />
<axis xyz="0 0 1"/>
<limit effort="1" velocity="20" lower="-0.29670597283903604735" upper="0.29670597283903604735"/>
<joint_properties friction="0.0"/>
</joint>

<link name="d4-2_urdf">
<visual>
<origin xyz="-0.079149999999999998135 -8.6736173798840354721e-19 -0.0087500000000000008327" rpy="-3.141592653589793116 -4.4379798391390675312e-19 -5.6380848503814306952e-20" />
<geometry>
<mesh filename="meshes/d4-2_urdf.stl"/>
</geometry>
<material name="d4-2_urdf_material">
<color rgba="0.34901960784313723618 0.37647058823529411242 0.4000000000000000222 1.0"/>
</material>
</visual>
<collision>
<origin xyz="-0.079149999999999998135 -8.6736173798840354721e-19 -0.0087500000000000008327" rpy="-3.141592653589793116 -4.4379798391390675312e-19 -5.6380848503814306952e-20" />
<geometry>
<mesh filename="meshes/d4-2_urdf.stl"/>
</geometry>
</collision>
<inertial>
<origin xyz="-0.0062842813664121671691 2.5879353753460549725e-10 -0.0081923602347070741819" rpy="0 0 0"/>
<mass value="0.007132231448786834245" />
<inertia ixx="4.8911025414963878454e-07" ixy="-2.0479711662898388297e-14"  ixz="1.4355227474224378679e-08" iyy="5.4026894403887895855e-07" iyz="1.5625068489926704385e-13" izz="7.1745332239577878067e-07" />
</inertial>
</link>

<link name="d3-2_urdf">
<visual>
<origin xyz="-0.063875000000000015099 0.0009999999999999731326 -0.0072500000000000463379" rpy="-1.5707963267948976682 -5.7868441810112084639e-16 -4.128432274470162884e-19" />
<geometry>
<mesh filename="meshes/d3-2_urdf.stl"/>
</geometry>
<material name="d3-2_urdf_material">
<color rgba="0.34901960784313723618 0.37647058823529411242 0.4000000000000000222 1.0"/>
</material>
</visual>
<collision>
<origin xyz="-0.063875000000000015099 0.0009999999999999731326 -0.0072500000000000463379" rpy="-1.5707963267948976682 -5.7868441810112084639e-16 -4.128432274470162884e-19" />
<geometry>
<mesh filename="meshes/d3-2_urdf.stl"/>
</geometry>
</collision>
<inertial>
<origin xyz="-0.00069598131543220642659 -0.013461728376310351865 -0.0072499999060333065667" rpy="0 0 0"/>
<mass value="0.0226148198830812934" />
<inertia ixx="4.0178611346720646775e-06" ixy="1.0347442960778385752e-07"  ixz="1.2277330080320219392e-14" iyy="1.3431972486148477499e-06" iyz="-4.2659478040114710519e-14" izz="4.0893383736852074447e-06" />
</inertial>
</link>

<link name="d2-2_urdf">
<visual>
<origin xyz="-0.0628749999999999587 0.038875000000000006772 -0.0067500000000000927314" rpy="-1.570796326794896558 -1.616246095983500399e-15 -1.1239805910186888482e-18" />
<geometry>
<mesh filename="meshes/d2-2_urdf.stl"/>
</geometry>
<material name="d2-2_urdf_material">
<color rgba="0.34901960784313723618 0.37647058823529411242 0.4000000000000000222 1.0"/>
</material>
</visual>
<collision>
<origin xyz="-0.0628749999999999587 0.038875000000000006772 -0.0067500000000000927314" rpy="-1.570796326794896558 -1.616246095983500399e-15 -1.1239805910186888482e-18" />
<geometry>
<mesh filename="meshes/d2-2_urdf.stl"/>
</geometry>
</collision>
<inertial>
<origin xyz="0.0084939436722220179599 -0.00026229267814973505901 -0.0067499976398635612093" rpy="0 0 0"/>
<mass value="0.011864989574403399242" />
<inertia ixx="5.4043476975481463473e-07" ixy="-5.8686598046442067655e-08"  ixz="4.1185672845562720939e-14" iyy="1.2212373681404815561e-06" iyz="1.4027559467782509233e-13" izz="1.1986582767037392264e-06" />
</inertial>
</link>

<link name="d1-2_urdf">
<visual>
<origin xyz="-0.088875000000000023426 0.038874999999999937383 -0.0062500000000000159595" rpy="-1.5707963267948961139 -8.8739653577863057829e-16 -8.6780554532362652871e-19" />
<geometry>
<mesh filename="meshes/d1-2_urdf.stl"/>
</geometry>
<material name="d1-2_urdf_material">
<color rgba="0.34901960784313723618 0.37647058823529411242 0.4000000000000000222 1.0"/>
</material>
</visual>
<collision>
<origin xyz="-0.088875000000000023426 0.038874999999999937383 -0.0062500000000000159595" rpy="-1.5707963267948961139 -8.8739653577863057829e-16 -8.6780554532362652871e-19" />
<geometry>
<mesh filename="meshes/d1-2_urdf.stl"/>
</geometry>
</collision>
<inertial>
<origin xyz="0.00081610826597226793222 0.0094232453162033900929 -0.0062500231253482425864" rpy="0 0 0"/>
<mass value="0.009662856642533072804" />
<inertia ixx="8.3693839580018411412e-07" ixy="1.4748701787318217242e-08"  ixz="1.3783262333701316031e-13" iyy="3.1465896345851299994e-07" iyz="2.2310472631819618516e-12" izz="8.3666691222579760474e-07" />
</inertial>
</link>

<joint name="ring_34" type="revolute">
<origin xyz="0.026000000000000217382 1.0997875787149835602e-17 -0.00050000000000001345452" rpy="4.9184194849935814842e-16 5.9160570651602741219e-16 -1.5707963267948952257" />
<parent link="d2-2_urdf" />
<child link="d1-2_urdf" />
<axis xyz="0 0 1"/>
<limit effort="1" velocity="20" lower="0" upper="1.570796326794896558"/>
<joint_properties friction="0.0"/>
</joint>

<joint name="ring_23" type="revolute">
<origin xyz="-0.0010000000000004540847 -0.037874999999999797717 -0.00050000000000015808709" rpy="4.6419088965683682166e-17 4.5000038854484199404e-15 -1.5707963267948970021" />
<parent link="d3-2_urdf" />
<child link="d2-2_urdf" />
<axis xyz="0 0 1"/>
<limit effort="1" velocity="20" lower="0" upper="1.570796326794896558"/>
<joint_properties friction="0.0"/>
</joint>

<joint name="ring_12" type="revolute">
<origin xyz="-0.015275000000000066303 0.0072500000000000116435 -0.0077499999999999045347" rpy="-1.5707963267948992225 -1.5707963267948885644 0" />
<parent link="d4-2_urdf" />
<child link="d3-2_urdf" />
<axis xyz="0 0 1"/>
<limit effort="1" velocity="20" lower="-0.034906585039886590949" upper="1.570796326794896558"/>
<joint_properties friction="0.0"/>
</joint>

<joint name="ring_01" type="revolute">
<origin xyz="-0.011784347123967246762 0.19516197601440882226 0.010513965579232013164" rpy="-0.087000830522749331153 0.0068123514634783575994 -1.5321205940965849646" />
<parent link="right_forearm_and_palm_assembly" />
<child link="d4-2_urdf" />
<axis xyz="0 0 1"/>
<limit effort="1" velocity="20" lower="-0.29670597283903604735" upper="0.29670597283903604735"/>
<joint_properties friction="0.0"/>
</joint>

<link name="d4-3_urdf">
<visual>
<origin xyz="-0.079149999999999998135 0 -0.0087499999999999990979" rpy="3.141592653589793116 -6.86274516867824596e-36 2.9272904565288895708e-32" />
<geometry>
<mesh filename="meshes/d4-3_urdf.stl"/>
</geometry>
<material name="d4-3_urdf_material">
<color rgba="0.34901960784313723618 0.37647058823529411242 0.4000000000000000222 1.0"/>
</material>
</visual>
<collision>
<origin xyz="-0.079149999999999998135 0 -0.0087499999999999990979" rpy="3.141592653589793116 -6.86274516867824596e-36 2.9272904565288895708e-32" />
<geometry>
<mesh filename="meshes/d4-3_urdf.stl"/>
</geometry>
</collision>
<inertial>
<origin xyz="-0.0062842813664121671691 2.5879353772487802785e-10 -0.0081923602347070724472" rpy="0 0 0"/>
<mass value="0.0071322314487868333777" />
<inertia ixx="4.8911025414963878454e-07" ixy="-2.0479711693406523578e-14"  ixz="1.4355227474224378679e-08" iyy="5.4026894403887853503e-07" iyz="1.5625068491580689482e-13" izz="7.1745332239577867479e-07" />
</inertial>
</link>

<link name="d3-3_urdf">
<visual>
<origin xyz="-0.063875000000000001221 0.0009999999999999731326 -0.0072500000000000463379" rpy="-1.5707963267948976682 -5.8880953492685354486e-16 1.6948183510606307051e-32" />
<geometry>
<mesh filename="meshes/d3-3_urdf.stl"/>
</geometry>
<material name="d3-3_urdf_material">
<color rgba="0.34901960784313723618 0.37647058823529411242 0.4000000000000000222 1.0"/>
</material>
</visual>
<collision>
<origin xyz="-0.063875000000000001221 0.0009999999999999731326 -0.0072500000000000463379" rpy="-1.5707963267948976682 -5.8880953492685354486e-16 1.6948183510606307051e-32" />
<geometry>
<mesh filename="meshes/d3-3_urdf.stl"/>
</geometry>
</collision>
<inertial>
<origin xyz="-0.0006959813154321925488 -0.013461728376310346661 -0.0072499999060333056994" rpy="0 0 0"/>
<mass value="0.022614819883081289931" />
<inertia ixx="4.0178611346720655246e-06" ixy="1.0347442960778381782e-07"  ixz="1.2277330139237473078e-14" iyy="1.3431972486148479617e-06" iyz="-4.2659478051237800744e-14" izz="4.0893383736852065977e-06" />
</inertial>
</link>

<link name="d2-3_urdf">
<visual>
<origin xyz="-0.062874999999999986455 0.038875000000000006772 -0.0067500000000000962008" rpy="-1.57079632679489678 -1.6156388965885127981e-15 -9.2444637330587320947e-32" />
<geometry>
<mesh filename="meshes/d2-3_urdf.stl"/>
</geometry>
<material name="d2-3_urdf_material">
<color rgba="0.34901960784313723618 0.37647058823529411242 0.4000000000000000222 1.0"/>
</material>
</visual>
<collision>
<origin xyz="-0.062874999999999986455 0.038875000000000006772 -0.0067500000000000962008" rpy="-1.57079632679489678 -1.6156388965885127981e-15 -9.2444637330587320947e-32" />
<geometry>
<mesh filename="meshes/d2-3_urdf.stl"/>
</geometry>
</collision>
<inertial>
<origin xyz="0.0084939436722220040821 -0.00026229267814973505901 -0.0067499976398635646788" rpy="0 0 0"/>
<mass value="0.011864989574403397507" />
<inertia ixx="5.4043476975481452885e-07" ixy="-5.868659804644208089e-08"  ixz="4.1185672877430025694e-14" iyy="1.2212373681404815561e-06" iyz="1.4027559464644640171e-13" izz="1.1986582767037392264e-06" />
</inertial>
</link>

<link name="d1-3_urdf">
<visual>
<origin xyz="-0.088875000000000009548 0.038875000000000048406 -0.0062500000000000159595" rpy="-1.5707963267948961139 -8.7170368868848065378e-16 5.8464010874321581202e-32" />
<geometry>
<mesh filename="meshes/d1-3_urdf.stl"/>
</geometry>
<material name="d1-3_urdf_material">
<color rgba="0.34901960784313723618 0.37647058823529411242 0.4000000000000000222 1.0"/>
</material>
</visual>
<collision>
<origin xyz="-0.088875000000000009548 0.038875000000000048406 -0.0062500000000000159595" rpy="-1.5707963267948961139 -8.7170368868848065378e-16 5.8464010874321581202e-32" />
<geometry>
<mesh filename="meshes/d1-3_urdf.stl"/>
</geometry>
</collision>
<inertial>
<origin xyz="0.00081610826597226793222 0.0094232453162035011152 -0.0062500231253482460558" rpy="0 0 0"/>
<mass value="0.0096628566425330745387" />
<inertia ixx="8.369383958001836906e-07" ixy="1.474870178731823544e-08"  ixz="1.378326234100062453e-13" iyy="3.1465896345851299994e-07" iyz="2.2310472631899682976e-12" izz="8.3666691222579718122e-07" />
</inertial>
</link>

<joint name="middle_34" type="revolute">
<origin xyz="0.02599999999999991207 -1.4755991567527715347e-16 -0.00050000000000009411916" rpy="1.374019371753883429e-15 1.010804088085701642e-15 -1.5707963267948958919" />
<parent link="d2-3_urdf" />
<child link="d1-3_urdf" />
<axis xyz="0 0 1"/>
<limit effort="1" velocity="20" lower="0" upper="1.570796326794896558"/>
<joint_properties friction="0.0"/>
</joint>

<joint name="middle_23" type="revolute">
<origin xyz="-0.0010000000000000451236 -0.037875000000000075273 -0.00049999999999995187183" rpy="1.4009774771081203282e-15 -5.8917067141199026395e-16 -1.5707963267948970021" />
<parent link="d3-3_urdf" />
<child link="d2-3_urdf" />
<axis xyz="0 0 1"/>
<limit effort="1" velocity="20" lower="0" upper="1.570796326794896558"/>
<joint_properties friction="0.0"/>
</joint>

<joint name="middle_12" type="revolute">
<origin xyz="-0.015274999999999983036 0.0072499999999999821532 -0.0077499999999999617806" rpy="-1.5707963267948941155 -1.5707963267948961139 0" />
<parent link="d4-3_urdf" />
<child link="d3-3_urdf" />
<axis xyz="0 0 1"/>
<limit effort="1" velocity="20" lower="-0.034906585039886590949" upper="1.570796326794896558"/>
<joint_properties friction="0.0"/>
</joint>

<joint name="middle_01" type="revolute">
<origin xyz="0.01173845611417019541 0.19914999999999996594 0.0080006470225533771884" rpy="-1.3866381960025091427e-17 1.1102487805056423062e-16 -1.5707963267948974462" />
<parent link="right_forearm_and_palm_assembly" />
<child link="d4-3_urdf" />
<axis xyz="0 0 1"/>
<limit effort="1" velocity="20" lower="-0.29670597283903604735" upper="0.29670597283903604735"/>
<joint_properties friction="0.0"/>
</joint>

<link name="d4-4_urdf">
<visual>
<origin xyz="-0.07915000000000002589 3.4694469519536141888e-18 -0.0087500000000000008327" rpy="-3.141592653589793116 5.6007022281921806211e-20 -6.3438766466273619014e-18" />
<geometry>
<mesh filename="meshes/d4-4_urdf.stl"/>
</geometry>
<material name="d4-4_urdf_material">
<color rgba="0.34901960784313723618 0.37647058823529411242 0.4000000000000000222 1.0"/>
</material>
</visual>
<collision>
<origin xyz="-0.07915000000000002589 3.4694469519536141888e-18 -0.0087500000000000008327" rpy="-3.141592653589793116 5.6007022281921806211e-20 -6.3438766466273619014e-18" />
<geometry>
<mesh filename="meshes/d4-4_urdf.stl"/>
</geometry>
</collision>
<inertial>
<origin xyz="-0.0062842813664121810469 2.5879353962136148059e-10 -0.0081923602347070741819" rpy="0 0 0"/>
<mass value="0.007132231448786834245" />
<inertia ixx="4.891102541496389963e-07" ixy="-2.0479711726762522457e-14"  ixz="1.4355227474224375371e-08" iyy="5.4026894403887874679e-07" iyz="1.5625068489808917986e-13" izz="7.1745332239577856891e-07" />
</inertial>
</link>

<link name="d3-4_urdf">
<visual>
<origin xyz="-0.063875000000000015099 0.0009999999999999731326 -0.0072500000000000480727" rpy="-1.5707963267948976682 -5.6991447625920315517e-16 -2.8317947779213194573e-20" />
<geometry>
<mesh filename="meshes/d3-4_urdf.stl"/>
</geometry>
<material name="d3-4_urdf_material">
<color rgba="0.34901960784313723618 0.37647058823529411242 0.4000000000000000222 1.0"/>
</material>
</visual>
<collision>
<origin xyz="-0.063875000000000015099 0.0009999999999999731326 -0.0072500000000000480727" rpy="-1.5707963267948976682 -5.6991447625920315517e-16 -2.8317947779213194573e-20" />
<geometry>
<mesh filename="meshes/d3-4_urdf.stl"/>
</geometry>
</collision>
<inertial>
<origin xyz="-0.00069598131543220631817 -0.01346172837631035013 -0.0072499999060333091688" rpy="0 0 0"/>
<mass value="0.022614819883081289931" />
<inertia ixx="4.0178611346719537162e-06" ixy="1.0347442960778404281e-07"  ixz="1.2277290757823639478e-14" iyy="1.3431972486147590232e-06" iyz="-4.2659478015462813542e-14" izz="4.0893383736852286205e-06" />
</inertial>
</link>

<link name="d2-4_urdf">
<visual>
<origin xyz="-0.062875000000000041966 0.038875000000000006772 -0.0067500000000000927314" rpy="-1.570796326794896558 -1.6200486936989597183e-15 -6.0967158515017657566e-19" />
<geometry>
<mesh filename="meshes/d2-4_urdf.stl"/>
</geometry>
<material name="d2-4_urdf_material">
<color rgba="0.34901960784313723618 0.37647058823529411242 0.4000000000000000222 1.0"/>
</material>
</visual>
<collision>
<origin xyz="-0.062875000000000041966 0.038875000000000006772 -0.0067500000000000927314" rpy="-1.570796326794896558 -1.6200486936989597183e-15 -6.0967158515017657566e-19" />
<geometry>
<mesh filename="meshes/d2-4_urdf.stl"/>
</geometry>
</collision>
<inertial>
<origin xyz="0.0084939436722219346931 -0.00026229267814974199791 -0.0067499976398635612093" rpy="0 0 0"/>
<mass value="0.011864989574403399242" />
<inertia ixx="5.4043476975481452885e-07" ixy="-5.8686598046442094125e-08"  ixz="4.1185672843946490095e-14" iyy="1.2212373681404819796e-06" iyz="1.4027559465922175794e-13" izz="1.1986582767037390146e-06" />
</inertial>
</link>

<link name="d1-4_urdf">
<visual>
<origin xyz="-0.088875000000000009548 0.038874999999999992895 -0.0062500000000000194289" rpy="-1.5707963267948961139 -8.8289208817102850906e-16 5.7463783702987361212e-19" />
<geometry>
<mesh filename="meshes/d1-4_urdf.stl"/>
</geometry>
<material name="d1-4_urdf_material">
<color rgba="0.34901960784313723618 0.37647058823529411242 0.4000000000000000222 1.0"/>
</material>
</visual>
<collision>
<origin xyz="-0.088875000000000009548 0.038874999999999992895 -0.0062500000000000194289" rpy="-1.5707963267948961139 -8.8289208817102850906e-16 5.7463783702987361212e-19" />
<geometry>
<mesh filename="meshes/d1-4_urdf.stl"/>
</geometry>
</collision>
<inertial>
<origin xyz="0.00081610826597225405443 0.0094232453162034490735 -0.0062500231253482469232" rpy="0 0 0"/>
<mass value="0.009662856642533072804" />
<inertia ixx="8.3693839580018347884e-07" ixy="1.4748701787318233785e-08"  ixz="1.3783262333889324935e-13" iyy="3.1465896345851289406e-07" iyz="2.2310472631917074771e-12" izz="8.3666691222579696946e-07" />
</inertial>
</link>

<joint name="index_34" type="revolute">
<origin xyz="0.025999999999999995337 1.8973538018496327595e-17 -0.00050000000000000044409" rpy="6.9057684691951674976e-15 1.7165371139413334888e-14 -1.5707963267948905628" />
<parent link="d2-4_urdf" />
<child link="d1-4_urdf" />
<axis xyz="0 0 1"/>
<limit effort="1" velocity="20" lower="0" upper="1.570796326794896558"/>
<joint_properties friction="0.0"/>
</joint>

<joint name="index_23" type="revolute">
<origin xyz="-0.00099999999999992456035 -0.037874999999999880984 -0.00049999999999984084953" rpy="-1.0736478731469521164e-15 -6.4972537115075657867e-15 -1.57079632679489678" />
<parent link="d3-4_urdf" />
<child link="d2-4_urdf" />
<axis xyz="0 0 1"/>
<limit effort="1" velocity="20" lower="0" upper="1.570796326794896558"/>
<joint_properties friction="0.0"/>
</joint>

<joint name="index_12" type="revolute">
<origin xyz="-0.015274999999999927525 0.0072500000000000168476 -0.0077499999999999912709" rpy="-1.5707963267948941155 -1.570796326794896336 0" />
<parent link="d4-4_urdf" />
<child link="d3-4_urdf" />
<axis xyz="0 0 1"/>
<limit effort="1" velocity="20" lower="-0.034906585039886590949" upper="1.570796326794896558"/>
<joint_properties friction="0.0"/>
</joint>

<joint name="index_01" type="revolute">
<origin xyz="0.03526125935230802616 0.19513802398559065843 0.010513965579232242148" rpy="0.087266462599716959625 5.9001432083974589266e-17 -1.6100662349647696381" />
<parent link="right_forearm_and_palm_assembly" />
<child link="d4-4_urdf" />
<axis xyz="0 0 1"/>
<limit effort="1" velocity="20" lower="-0.29670597283903604735" upper="0.29670597283903604735"/>
<joint_properties friction="0.0"/>
</joint>


</robot>
